Workbook

Sheet Partidos
A1: ID Partido | B1: Goles Eq1 | C1: GolesEq2
A2: 1 | B2: 1 | C2: 3
A3: 2 | B3: 3 | C3: 3
A4: 3 | B4: 2 | C4: 2
A5: 4 | B5: 4 | C5: 1
A6: 5 | B6: 5 | C6: 2
A7: 6 | B7: 6 | C7: 3
A8: 7 | B8: 3 | C8: 4
A9: 8 | B9: 2 | C9: 5
A10: 9 | B10: 1 | C10: 78
A11: 10 | B11: 2 | C11: 99
A12: 11 | B12: 3 | C12: 0
A13: 12 | B13: 4 | C13: 0
... A20: 19 | B20: 2 | C20: 1
A21: 20
A22: 21
A23: 22
A24: 23
A25: 24
A26: 25
A27: 26
A28: 27
A29: 28
A30: 29
A31: 30
A32: 31
... A37: 36

Sheet Top
A1: Jugadores | B1: Puntos | D1: Puesto | E1: Lider | F1: Puntaje
A2: Juan | B2: {=INDIRECT(A2 & "!E2")} -> 23 | D2: 1 | E2: {=_xlfn.TAKE(_xlfn._xlws.SORT(_xlfn._xlws.FILTER(A2:B50, A2:A50<>""), 2, -1), 10)} -> Jose | F2: 48
A3: Pedro | B3: {=INDIRECT(A3 & "!E2")} -> 16 | D3: 2 | E3: Inti | F3: 42
A4: Inti | B4: {=INDIRECT(A4 & "!E2")} -> 42 | D4: 3 | E4: Juan | F4: 23
A5: Pepe | B5: {=INDIRECT(A5 & "!E2")} -> 0 | D5: 4 | E5: Elizabeth | F5: 23
A6: Elizabeth | B6: {=INDIRECT(A6 & "!E2")} -> 23 | D6: 5 | E6: Pablo | F6: 23
A7: Jose | B7: {=INDIRECT(A7 & "!E2")} -> 48 | D7: 6 | E7: joaquin | F7: 23
A8: Pablo | B8: {=INDIRECT(A8 & "!E2")} -> 23 | D8: 7 | E8: Vale | F8: 23
A9: joaquin | B9: {=INDIRECT(A9 & "!E2")} -> 23 | D9: 8 | E9: Mariano | F9: 23
A10: Vale | B10: {=INDIRECT(A10 & "!E2")} -> 23 | D10: 9 | E10: Jorge | F10: 23
A11: Mariano | B11: {=INDIRECT(A11 & "!E2")} -> 23 | D11: 10 | E11: Pedro | F11: 16
A12: Jorge | B12: {=INDIRECT(A12 & "!E2")} -> 23

Sheet Jose
A1: ID Partido | B1: predict Eq1 | C1: PredictEq2 | D1: puntos | E1: Puntos totales
A2: 1 | B2: 1 | C2: 2 | D2: =IFERROR(IF(OR(VLOOKUP(A2, Partidos!$A:$C, 2, 0)="", VLOOKUP(A2, Partidos!$A:$C, 3, 0)=""), 0, IF(SIGN(VLOOKUP(A2, Partidos!$A:$C, 2, 0) - VLOOKUP(A2, Partidos!$A:$C, 3, 0)) = SIGN(B2 - C2), 2 + IF((VLOOKUP(A2, Partidos!$A:$C, 2, 0) - VLOOKUP(A2, Partidos!$A:$C, 3, 0)) = (B2 - C2), 3 + IF(AND(VLOOKUP(A2, Partidos!$A:$C, 2, 0) = B2, VLOOKUP(A2, Partidos!$A:$C, 3, 0) = C2), 2, 0), 0), 0)), 0) -> 2 | E2: =_xlfn.AGGREGATE(9, 6, D2:D100) -> 48
A3: 2 | B3: 3 | C3: 1 | D3: =IFERROR(IF(OR(VLOOKUP(A3, Partidos!$A:$C, 2, 0)="", VLOOKUP(A3, Partidos!$A:$C, 3, 0)=""), 0, IF(SIGN(VLOOKUP(A3, Partidos!$A:$C, 2, 0) - VLOOKUP(A3, Partidos!$A:$C, 3, 0)) = SIGN(B3 - C3), 2 + IF((VLOOKUP(A3, Partidos!$A:$C, 2, 0) - VLOOKUP(A3, Partidos!$A:$C, 3, 0)) = (B3 - C3), 3 + IF(AND(VLOOKUP(A3, Partidos!$A:$C, 2, 0) = B3, VLOOKUP(A3, Partidos!$A:$C, 3, 0) = C3), 2, 0), 0), 0)), 0) -> 0
A4: 3 | B4: 1 | C4: 2 | D4: =IFERROR(IF(OR(VLOOKUP(A4, Partidos!$A:$C, 2, 0)="", VLOOKUP(A4, Partidos!$A:$C, 3, 0)=""), 0, IF(SIGN(VLOOKUP(A4, Partidos!$A:$C, 2, 0) - VLOOKUP(A4, Partidos!$A:$C, 3, 0)) = SIGN(B4 - C4), 2 + IF((VLOOKUP(A4, Partidos!$A:$C, 2, 0) - VLOOKUP(A4, Partidos!$A:$C, 3, 0)) = (B4 - C4), 3 + IF(AND(VLOOKUP(A4, Partidos!$A:$C, 2, 0) = B4, VLOOKUP(A4, Partidos!$A:$C, 3, 0) = C4), 2, 0), 0), 0)), 0) -> 0
A5: 4 | B5: 3 | C5: 2 | D5: =IFERROR(IF(OR(VLOOKUP(A5, Partidos!$A:$C, 2, 0)="", VLOOKUP(A5, Partidos!$A:$C, 3, 0)=""), 0, IF(SIGN(VLOOKUP(A5, Partidos!$A:$C, 2, 0) - VLOOKUP(A5, Partidos!$A:$C, 3, 0)) = SIGN(B5 - C5), 2 + IF((VLOOKUP(A5, Partidos!$A:$C, 2, 0) - VLOOKUP(A5, Partidos!$A:$C, 3, 0)) = (B5 - C5), 3 + IF(AND(VLOOKUP(A5, Partidos!$A:$C, 2, 0) = B5, VLOOKUP(A5, Partidos!$A:$C, 3, 0) = C5), 2, 0), 0), 0)), 0) -> 2
A6: 5 | B6: 5 | C6: 2 | D6: =IFERROR(IF(OR(VLOOKUP(A6, Partidos!$A:$C, 2, 0)="", VLOOKUP(A6, Partidos!$A:$C, 3, 0)=""), 0, IF(SIGN(VLOOKUP(A6, Partidos!$A:$C, 2, 0) - VLOOKUP(A6, Partidos!$A:$C, 3, 0)) = SIGN(B6 - C6), 2 + IF((VLOOKUP(A6, Partidos!$A:$C, 2, 0) - VLOOKUP(A6, Partidos!$A:$C, 3, 0)) = (B6 - C6), 3 + IF(AND(VLOOKUP(A6, Partidos!$A:$C, 2, 0) = B6, VLOOKUP(A6, Partidos!$A:$C, 3, 0) = C6), 2, 0), 0), 0)), 0) -> 7
A7: 6 | B7: 7 | C7: 2 | D7: =IFERROR(IF(OR(VLOOKUP(A7, Partidos!$A:$C, 2, 0)="", VLOOKUP(A7, Partidos!$A:$C, 3, 0)=""), 0, IF(SIGN(VLOOKUP(A7, Partidos!$A:$C, 2, 0) - VLOOKUP(A7, Partidos!$A:$C, 3, 0)) = SIGN(B7 - C7), 2 + IF((VLOOKUP(A7, Partidos!$A:$C, 2, 0) - VLOOKUP(A7, Partidos!$A:$C, 3, 0)) = (B7 - C7), 3 + IF(AND(VLOOKUP(A7, Partidos!$A:$C, 2, 0) = B7, VLOOKUP(A7, Partidos!$A:$C, 3, 0) = C7), 2, 0), 0), 0)), 0) -> 2
A8: 7 | B8: 1 | C8: 2 | D8: =IFERROR(IF(OR(VLOOKUP(A8, Partidos!$A:$C, 2, 0)="", VLOOKUP(A8, Partidos!$A:$C, 3, 0)=""), 0, IF(SIGN(VLOOKUP(A8, Partidos!$A:$C, 2, 0) - VLOOKUP(A8, Partidos!$A:$C, 3, 0)) = SIGN(B8 - C8), 2 + IF((VLOOKUP(A8, Partidos!$A:$C, 2, 0) - VLOOKUP(A8, Partidos!$A:$C, 3, 0)) = (B8 - C8), 3 + IF(AND(VLOOKUP(A8, Partidos!$A:$C, 2, 0) = B8, VLOOKUP(A8, Partidos!$A:$C, 3, 0) = C8), 2, 0), 0), 0)), 0) -> 5
A9: 8 | B9: 2 | C9: 2 | D9: =IFERROR(IF(OR(VLOOKUP(A9, Partidos!$A:$C, 2, 0)="", VLOOKUP(A9, Partidos!$A:$C, 3, 0)=""), 0, IF(SIGN(VLOOKUP(A9, Partidos!$A:$C, 2, 0) - VLOOKUP(A9, Partidos!$A:$C, 3, 0)) = SIGN(B9 - C9), 2 + IF((VLOOKUP(A9, Partidos!$A:$C, 2, 0) - VLOOKUP(A9, Partidos!$A:$C, 3, 0)) = (B9 - C9), 3 + IF(AND(VLOOKUP(A9, Partidos!$A:$C, 2, 0) = B9, VLOOKUP(A9, Partidos!$A:$C, 3, 0) = C9), 2, 0), 0), 0)), 0) -> 0
A10: 9 | B10: 2 | C10: 2 | D10: =IFERROR(IF(OR(VLOOKUP(A10, Partidos!$A:$C, 2, 0)="", VLOOKUP(A10, Partidos!$A:$C, 3, 0)=""), 0, IF(SIGN(VLOOKUP(A10, Partidos!$A:$C, 2, 0) - VLOOKUP(A10, Partidos!$A:$C, 3, 0)) = SIGN(B10 - C10), 2 + IF((VLOOKUP(A10, Partidos!$A:$C, 2, 0) - VLOOKUP(A10, Partidos!$A:$C, 3, 0)) = (B10 - C10), 3 + IF(AND(VLOOKUP(A10, Partidos!$A:$C, 2, 0) = B10, VLOOKUP(A10, Partidos!$A:$C, 3, 0) = C10), 2, 0), 0), 0)), 0) -> 0
A11: 10 | B11: 1 | C11: 2 | D11: =IFERROR(IF(OR(VLOOKUP(A11, Partidos!$A:$C, 2, 0)="", VLOOKUP(A11, Partidos!$A:$C, 3, 0)=""), 0, IF(SIGN(VLOOKUP(A11, Partidos!$A:$C, 2, 0) - VLOOKUP(A11, Partidos!$A:$C, 3, 0)) = SIGN(B11 - C11), 2 + IF((VLOOKUP(A11, Partidos!$A:$C, 2, 0) - VLOOKUP(A11, Partidos!$A:$C, 3, 0)) = (B11 - C11), 3 + IF(AND(VLOOKUP(A11, Partidos!$A:$C, 2, 0) = B11, VLOOKUP(A11, Partidos!$A:$C, 3, 0) = C11), 2, 0), 0), 0)), 0) -> 2
A12: 11 | B12: 0 | C12: 2 | D12: =IFERROR(IF(OR(VLOOKUP(A12, Partidos!$A:$C, 2, 0)="", VLOOKUP(A12, Partidos!$A:$C, 3, 0)=""), 0, IF(SIGN(VLOOKUP(A12, Partidos!$A:$C, 2, 0) - VLOOKUP(A12, Partidos!$A:$C, 3, 0)) = SIGN(B12 - C12), 2 + IF((VLOOKUP(A12, Partidos!$A:$C, 2, 0) - VLOOKUP(A12, Partidos!$A:$C, 3, 0)) = (B12 - C12), 3 + IF(AND(VLOOKUP(A12, Partidos!$A:$C, 2, 0) = B12, VLOOKUP(A12, Partidos!$A:$C, 3, 0) = C12), 2, 0), 0), 0)), 0) -> 0
A13: 12 | B13: 0 | C13: 2 | D13: =IFERROR(IF(OR(VLOOKUP(A13, Partidos!$A:$C, 2, 0)="", VLOOKUP(A13, Partidos!$A:$C, 3, 0)=""), 0, IF(SIGN(VLOOKUP(A13, Partidos!$A:$C, 2, 0) - VLOOKUP(A13, Partidos!$A:$C, 3, 0)) = SIGN(B13 - C13), 2 + IF((VLOOKUP(A13, Partidos!$A:$C, 2, 0) - VLOOKUP(A13, Partidos!$A:$C, 3, 0)) = (B13 - C13), 3 + IF(AND(VLOOKUP(A13, Partidos!$A:$C, 2, 0) = B13, VLOOKUP(A13, Partidos!$A:$C, 3, 0) = C13), 2, 0), 0), 0)), 0) -> 0
A14: 13 | B14: 0 | C14: 0 | D14: =IFERROR(IF(OR(VLOOKUP(A14, Partidos!$A:$C, 2, 0)="", VLOOKUP(A14, Partidos!$A:$C, 3, 0)=""), 0, IF(SIGN(VLOOKUP(A14, Partidos!$A:$C, 2, 0) - VLOOKUP(A14, Partidos!$A:$C, 3, 0)) = SIGN(B14 - C14), 2 + IF((VLOOKUP(A14, Partidos!$A:$C, 2, 0) - VLOOKUP(A14, Partidos!$A:$C, 3, 0)) = (B14 - C14), 3 + IF(AND(VLOOKUP(A14, Partidos!$A:$C, 2, 0) = B14, VLOOKUP(A14, Partidos!$A:$C, 3, 0) = C14), 2, 0), 0), 0)), 0) -> 0
... A26: 25 | B26: 2 | C26: 1 | D26: =IFERROR(IF(OR(VLOOKUP(A26, Partidos!$A:$C, 2, 0)="", VLOOKUP(A26, Partidos!$A:$C, 3, 0)=""), 0, IF(SIGN(VLOOKUP(A26, Partidos!$A:$C, 2, 0) - VLOOKUP(A26, Partidos!$A:$C, 3, 0)) = SIGN(B26 - C26), 2 + IF((VLOOKUP(A26, Partidos!$A:$C, 2, 0) - VLOOKUP(A26, Partidos!$A:$C, 3, 0)) = (B26 - C26), 3 + IF(AND(VLOOKUP(A26, Partidos!$A:$C, 2, 0) = B26, VLOOKUP(A26, Partidos!$A:$C, 3, 0) = C26), 2, 0), 0), 0)), 0) -> 0
D27: =IFERROR(IF(OR(VLOOKUP(A27, Partidos!$A:$C, 2, 0)="", VLOOKUP(A27, Partidos!$A:$C, 3, 0)=""), 0, IF(SIGN(VLOOKUP(A27, Partidos!$A:$C, 2, 0) - VLOOKUP(A27, Partidos!$A:$C, 3, 0)) = SIGN(B27 - C27), 2 + IF((VLOOKUP(A27, Partidos!$A:$C, 2, 0) - VLOOKUP(A27, Partidos!$A:$C, 3, 0)) = (B27 - C27), 3 + IF(AND(VLOOKUP(A27, Partidos!$A:$C, 2, 0) = B27, VLOOKUP(A27, Partidos!$A:$C, 3, 0) = C27), 2, 0), 0), 0)), 0) -> 0

Sheet Inti
A1: ID Partido | B1: predict Eq1 | C1: PredictEq2 | D1: puntos | E1: Puntos totales
A2: 1 | B2: 1 | C2: 3 | D2: =IFERROR(IF(OR(VLOOKUP(A2, Partidos!$A:$C, 2, 0)="", VLOOKUP(A2, Partidos!$A:$C, 3, 0)=""), 0, IF(SIGN(VLOOKUP(A2, Partidos!$A:$C, 2, 0) - VLOOKUP(A2, Partidos!$A:$C, 3, 0)) = SIGN(B2 - C2), 2 + IF((VLOOKUP(A2, Partidos!$A:$C, 2, 0) - VLOOKUP(A2, Partidos!$A:$C, 3, 0)) = (B2 - C2), 3 + IF(AND(VLOOKUP(A2, Partidos!$A:$C, 2, 0) = B2, VLOOKUP(A2, Partidos!$A:$C, 3, 0) = C2), 2, 0), 0), 0)), 0) -> 7 | E2: =_xlfn.AGGREGATE(9, 6, D2:D100) -> 42
A3: 2 | B3: 3 | C3: 1 | D3: =IFERROR(IF(OR(VLOOKUP(A3, Partidos!$A:$C, 2, 0)="", VLOOKUP(A3, Partidos!$A:$C, 3, 0)=""), 0, IF(SIGN(VLOOKUP(A3, Partidos!$A:$C, 2, 0) - VLOOKUP(A3, Partidos!$A:$C, 3, 0)) = SIGN(B3 - C3), 2 + IF((VLOOKUP(A3, Partidos!$A:$C, 2, 0) - VLOOKUP(A3, Partidos!$A:$C, 3, 0)) = (B3 - C3), 3 + IF(AND(VLOOKUP(A3, Partidos!$A:$C, 2, 0) = B3, VLOOKUP(A3, Partidos!$A:$C, 3, 0) = C3), 2, 0), 0), 0)), 0) -> 0
A4: 3 | B4: 2 | C4: 2 | D4: =IFERROR(IF(OR(VLOOKUP(A4, Partidos!$A:$C, 2, 0)="", VLOOKUP(A4, Partidos!$A:$C, 3, 0)=""), 0, IF(SIGN(VLOOKUP(A4, Partidos!$A:$C, 2, 0) - VLOOKUP(A4, Partidos!$A:$C, 3, 0)) = SIGN(B4 - C4), 2 + IF((VLOOKUP(A4, Partidos!$A:$C, 2, 0) - VLOOKUP(A4, Partidos!$A:$C, 3, 0)) = (B4 - C4), 3 + IF(AND(VLOOKUP(A4, Partidos!$A:$C, 2, 0) = B4, VLOOKUP(A4, Partidos!$A:$C, 3, 0) = C4), 2, 0), 0), 0)), 0) -> 7
A5: 4 | B5: 2 | C5: 2 | D5: =IFERROR(IF(OR(VLOOKUP(A5, Partidos!$A:$C, 2, 0)="", VLOOKUP(A5, Partidos!$A:$C, 3, 0)=""), 0, IF(SIGN(VLOOKUP(A5, Partidos!$A:$C, 2, 0) - VLOOKUP(A5, Partidos!$A:$C, 3, 0)) = SIGN(B5 - C5), 2 + IF((VLOOKUP(A5, Partidos!$A:$C, 2, 0) - VLOOKUP(A5, Partidos!$A:$C, 3, 0)) = (B5 - C5), 3 + IF(AND(VLOOKUP(A5, Partidos!$A:$C, 2, 0) = B5, VLOOKUP(A5, Partidos!$A:$C, 3, 0) = C5), 2, 0), 0), 0)), 0) -> 0
A6: 5 | B6: 4 | C6: 1 | D6: =IFERROR(IF(OR(VLOOKUP(A6, Partidos!$A:$C, 2, 0)="", VLOOKUP(A6, Partidos!$A:$C, 3, 0)=""), 0, IF(SIGN(VLOOKUP(A6, Partidos!$A:$C, 2, 0) - VLOOKUP(A6, Partidos!$A:$C, 3, 0)) = SIGN(B6 - C6), 2 + IF((VLOOKUP(A6, Partidos!$A:$C, 2, 0) - VLOOKUP(A6, Partidos!$A:$C, 3, 0)) = (B6 - C6), 3 + IF(AND(VLOOKUP(A6, Partidos!$A:$C, 2, 0) = B6, VLOOKUP(A6, Partidos!$A:$C, 3, 0) = C6), 2, 0), 0), 0)), 0) -> 5
A7: 6 | B7: 2 | C7: 2 | D7: =IFERROR(IF(OR(VLOOKUP(A7, Partidos!$A:$C, 2, 0)="", VLOOKUP(A7, Partidos!$A:$C, 3, 0)=""), 0, IF(SIGN(VLOOKUP(A7, Partidos!$A:$C, 2, 0) - VLOOKUP(A7, Partidos!$A:$C, 3, 0)) = SIGN(B7 - C7), 2 + IF((VLOOKUP(A7, Partidos!$A:$C, 2, 0) - VLOOKUP(A7, Partidos!$A:$C, 3, 0)) = (B7 - C7), 3 + IF(AND(VLOOKUP(A7, Partidos!$A:$C, 2, 0) = B7, VLOOKUP(A7, Partidos!$A:$C, 3, 0) = C7), 2, 0), 0), 0)), 0) -> 0
A8: 7 | B8: 2 | C8: 2 | D8: =IFERROR(IF(OR(VLOOKUP(A8, Partidos!$A:$C, 2, 0)="", VLOOKUP(A8, Partidos!$A:$C, 3, 0)=""), 0, IF(SIGN(VLOOKUP(A8, Partidos!$A:$C, 2, 0) - VLOOKUP(A8, Partidos!$A:$C, 3, 0)) = SIGN(B8 - C8), 2 + IF((VLOOKUP(A8, Partidos!$A:$C, 2, 0) - VLOOKUP(A8, Partidos!$A:$C, 3, 0)) = (B8 - C8), 3 + IF(AND(VLOOKUP(A8, Partidos!$A:$C, 2, 0) = B8, VLOOKUP(A8, Partidos!$A:$C, 3, 0) = C8), 2, 0), 0), 0)), 0) -> 0
A9: 8 | B9: 2 | C9: 2 | D9: =IFERROR(IF(OR(VLOOKUP(A9, Partidos!$A:$C, 2, 0)="", VLOOKUP(A9, Partidos!$A:$C, 3, 0)=""), 0, IF(SIGN(VLOOKUP(A9, Partidos!$A:$C, 2, 0) - VLOOKUP(A9, Partidos!$A:$C, 3, 0)) = SIGN(B9 - C9), 2 + IF((VLOOKUP(A9, Partidos!$A:$C, 2, 0) - VLOOKUP(A9, Partidos!$A:$C, 3, 0)) = (B9 - C9), 3 + IF(AND(VLOOKUP(A9, Partidos!$A:$C, 2, 0) = B9, VLOOKUP(A9, Partidos!$A:$C, 3, 0) = C9), 2, 0), 0), 0)), 0) -> 0
A10: 9 | B10: 2 | C10: 2 | D10: =IFERROR(IF(OR(VLOOKUP(A10, Partidos!$A:$C, 2, 0)="", VLOOKUP(A10, Partidos!$A:$C, 3, 0)=""), 0, IF(SIGN(VLOOKUP(A10, Partidos!$A:$C, 2, 0) - VLOOKUP(A10, Partidos!$A:$C, 3, 0)) = SIGN(B10 - C10), 2 + IF((VLOOKUP(A10, Partidos!$A:$C, 2, 0) - VLOOKUP(A10, Partidos!$A:$C, 3, 0)) = (B10 - C10), 3 + IF(AND(VLOOKUP(A10, Partidos!$A:$C, 2, 0) = B10, VLOOKUP(A10, Partidos!$A:$C, 3, 0) = C10), 2, 0), 0), 0)), 0) -> 0
A11: 10 | B11: 2 | C11: 2 | D11: =IFERROR(IF(OR(VLOOKUP(A11, Partidos!$A:$C, 2, 0)="", VLOOKUP(A11, Partidos!$A:$C, 3, 0)=""), 0, IF(SIGN(VLOOKUP(A11, Partidos!$A:$C, 2, 0) - VLOOKUP(A11, Partidos!$A:$C, 3, 0)) = SIGN(B11 - C11), 2 + IF((VLOOKUP(A11, Partidos!$A:$C, 2, 0) - VLOOKUP(A11, Partidos!$A:$C, 3, 0)) = (B11 - C11), 3 + IF(AND(VLOOKUP(A11, Partidos!$A:$C, 2, 0) = B11, VLOOKUP(A11, Partidos!$A:$C, 3, 0) = C11), 2, 0), 0), 0)), 0) -> 0
A12: 11 | B12: 2 | C12: 2 | D12: =IFERROR(IF(OR(VLOOKUP(A12, Partidos!$A:$C, 2, 0)="", VLOOKUP(A12, Partidos!$A:$C, 3, 0)=""), 0, IF(SIGN(VLOOKUP(A12, Partidos!$A:$C, 2, 0) - VLOOKUP(A12, Partidos!$A:$C, 3, 0)) = SIGN(B12 - C12), 2 + IF((VLOOKUP(A12, Partidos!$A:$C, 2, 0) - VLOOKUP(A12, Partidos!$A:$C, 3, 0)) = (B12 - C12), 3 + IF(AND(VLOOKUP(A12, Partidos!$A:$C, 2, 0) = B12, VLOOKUP(A12, Partidos!$A:$C, 3, 0) = C12), 2, 0), 0), 0)), 0) -> 0
A13: 12 | B13: 2 | C13: 2 | D13: =IFERROR(IF(OR(VLOOKUP(A13, Partidos!$A:$C, 2, 0)="", VLOOKUP(A13, Partidos!$A:$C, 3, 0)=""), 0, IF(SIGN(VLOOKUP(A13, Partidos!$A:$C, 2, 0) - VLOOKUP(A13, Partidos!$A:$C, 3, 0)) = SIGN(B13 - C13), 2 + IF((VLOOKUP(A13, Partidos!$A:$C, 2, 0) - VLOOKUP(A13, Partidos!$A:$C, 3, 0)) = (B13 - C13), 3 + IF(AND(VLOOKUP(A13, Partidos!$A:$C, 2, 0) = B13, VLOOKUP(A13, Partidos!$A:$C, 3, 0) = C13), 2, 0), 0), 0)), 0) -> 0
A14: 13 | B14: 2 | C14: 2 | D14: =IFERROR(IF(OR(VLOOKUP(A14, Partidos!$A:$C, 2, 0)="", VLOOKUP(A14, Partidos!$A:$C, 3, 0)=""), 0, IF(SIGN(VLOOKUP(A14, Partidos!$A:$C, 2, 0) - VLOOKUP(A14, Partidos!$A:$C, 3, 0)) = SIGN(B14 - C14), 2 + IF((VLOOKUP(A14, Partidos!$A:$C, 2, 0) - VLOOKUP(A14, Partidos!$A:$C, 3, 0)) = (B14 - C14), 3 + IF(AND(VLOOKUP(A14, Partidos!$A:$C, 2, 0) = B14, VLOOKUP(A14, Partidos!$A:$C, 3, 0) = C14), 2, 0), 0), 0)), 0) -> 0
... A26: 25 | B26: 2 | C26: 3 | D26: =IFERROR(IF(OR(VLOOKUP(A26, Partidos!$A:$C, 2, 0)="", VLOOKUP(A26, Partidos!$A:$C, 3, 0)=""), 0, IF(SIGN(VLOOKUP(A26, Partidos!$A:$C, 2, 0) - VLOOKUP(A26, Partidos!$A:$C, 3, 0)) = SIGN(B26 - C26), 2 + IF((VLOOKUP(A26, Partidos!$A:$C, 2, 0) - VLOOKUP(A26, Partidos!$A:$C, 3, 0)) = (B26 - C26), 3 + IF(AND(VLOOKUP(A26, Partidos!$A:$C, 2, 0) = B26, VLOOKUP(A26, Partidos!$A:$C, 3, 0) = C26), 2, 0), 0), 0)), 0) -> 0
D27: =IFERROR(IF(OR(VLOOKUP(A27, Partidos!$A:$C, 2, 0)="", VLOOKUP(A27, Partidos!$A:$C, 3, 0)=""), 0, IF(SIGN(VLOOKUP(A27, Partidos!$A:$C, 2, 0) - VLOOKUP(A27, Partidos!$A:$C, 3, 0)) = SIGN(B27 - C27), 2 + IF((VLOOKUP(A27, Partidos!$A:$C, 2, 0) - VLOOKUP(A27, Partidos!$A:$C, 3, 0)) = (B27 - C27), 3 + IF(AND(VLOOKUP(A27, Partidos!$A:$C, 2, 0) = B27, VLOOKUP(A27, Partidos!$A:$C, 3, 0) = C27), 2, 0), 0), 0)), 0) -> 0

Sheet Vale
A1: ID Partido | B1: predict Eq1 | C1: PredictEq2 | D1: puntos | E1: Puntos totales
A2: 1 | B2: 1 | C2: 3 | D2: =IFERROR(IF(OR(VLOOKUP(A2, Partidos!$A:$C, 2, 0)="", VLOOKUP(A2, Partidos!$A:$C, 3, 0)=""), 0, IF(SIGN(VLOOKUP(A2, Partidos!$A:$C, 2, 0) - VLOOKUP(A2, Partidos!$A:$C, 3, 0)) = SIGN(B2 - C2), 2 + IF((VLOOKUP(A2, Partidos!$A:$C, 2, 0) - VLOOKUP(A2, Partidos!$A:$C, 3, 0)) = (B2 - C2), 3 + IF(AND(VLOOKUP(A2, Partidos!$A:$C, 2, 0) = B2, VLOOKUP(A2, Partidos!$A:$C, 3, 0) = C2), 2, 0), 0), 0)), 0) -> 7 | E2: =_xlfn.AGGREGATE(9, 6, D2:D100) -> 23
A3: 2 | B3: 3 | C3: 1 | D3: =IFERROR(IF(OR(VLOOKUP(A3, Partidos!$A:$C, 2, 0)="", VLOOKUP(A3, Partidos!$A:$C, 3, 0)=""), 0, IF(SIGN(VLOOKUP(A3, Partidos!$A:$C, 2, 0) - VLOOKUP(A3, Partidos!$A:$C, 3, 0)) = SIGN(B3 - C3), 2 + IF((VLOOKUP(A3, Partidos!$A:$C, 2, 0) - VLOOKUP(A3, Partidos!$A:$C, 3, 0)) = (B3 - C3), 3 + IF(AND(VLOOKUP(A3, Partidos!$A:$C, 2, 0) = B3, VLOOKUP(A3, Partidos!$A:$C, 3, 0) = C3), 2, 0), 0), 0)), 0) -> 0
A4: 3 | B4: 2 | C4: 2 | D4: =IFERROR(IF(OR(VLOOKUP(A4, Partidos!$A:$C, 2, 0)="", VLOOKUP(A4, Partidos!$A:$C, 3, 0)=""), 0, IF(SIGN(VLOOKUP(A4, Partidos!$A:$C, 2, 0) - VLOOKUP(A4, Partidos!$A:$C, 3, 0)) = SIGN(B4 - C4), 2 + IF((VLOOKUP(A4, Partidos!$A:$C, 2, 0) - VLOOKUP(A4, Partidos!$A:$C, 3, 0)) = (B4 - C4), 3 + IF(AND(VLOOKUP(A4, Partidos!$A:$C, 2, 0) = B4, VLOOKUP(A4, Partidos!$A:$C, 3, 0) = C4), 2, 0), 0), 0)), 0) -> 7
A5: 4 | B5: 2 | C5: 2 | D5: =IFERROR(IF(OR(VLOOKUP(A5, Partidos!$A:$C, 2, 0)="", VLOOKUP(A5, Partidos!$A:$C, 3, 0)=""), 0, IF(SIGN(VLOOKUP(A5, Partidos!$A:$C, 2, 0) - VLOOKUP(A5, Partidos!$A:$C, 3, 0)) = SIGN(B5 - C5), 2 + IF((VLOOKUP(A5, Partidos!$A:$C, 2, 0) - VLOOKUP(A5, Partidos!$A:$C, 3, 0)) = (B5 - C5), 3 + IF(AND(VLOOKUP(A5, Partidos!$A:$C, 2, 0) = B5, VLOOKUP(A5, Partidos!$A:$C, 3, 0) = C5), 2, 0), 0), 0)), 0) -> 0
A6: 5 | B6: 2 | C6: 2 | D6: =IFERROR(IF(OR(VLOOKUP(A6, Partidos!$A:$C, 2, 0)="", VLOOKUP(A6, Partidos!$A:$C, 3, 0)=""), 0, IF(SIGN(VLOOKUP(A6, Partidos!$A:$C, 2, 0) - VLOOKUP(A6, Partidos!$A:$C, 3, 0)) = SIGN(B6 - C6), 2 + IF((VLOOKUP(A6, Partidos!$A:$C, 2, 0) - VLOOKUP(A6, Partidos!$A:$C, 3, 0)) = (B6 - C6), 3 + IF(AND(VLOOKUP(A6, Partidos!$A:$C, 2, 0) = B6, VLOOKUP(A6, Partidos!$A:$C, 3, 0) = C6), 2, 0), 0), 0)), 0) -> 0
A7: 6 | B7: 2 | C7: 2 | D7: =IFERROR(IF(OR(VLOOKUP(A7, Partidos!$A:$C, 2, 0)="", VLOOKUP(A7, Partidos!$A:$C, 3, 0)=""), 0, IF(SIGN(VLOOKUP(A7, Partidos!$A:$C, 2, 0) - VLOOKUP(A7, Partidos!$A:$C, 3, 0)) = SIGN(B7 - C7), 2 + IF((VLOOKUP(A7, Partidos!$A:$C, 2, 0) - VLOOKUP(A7, Partidos!$A:$C, 3, 0)) = (B7 - C7), 3 + IF(AND(VLOOKUP(A7, Partidos!$A:$C, 2, 0) = B7, VLOOKUP(A7, Partidos!$A:$C, 3, 0) = C7), 2, 0), 0), 0)), 0) -> 0
A8: 7 | B8: 2 | C8: 2 | D8: =IFERROR(IF(OR(VLOOKUP(A8, Partidos!$A:$C, 2, 0)="", VLOOKUP(A8, Partidos!$A:$C, 3, 0)=""), 0, IF(SIGN(VLOOKUP(A8, Partidos!$A:$C, 2, 0) - VLOOKUP(A8, Partidos!$A:$C, 3, 0)) = SIGN(B8 - C8), 2 + IF((VLOOKUP(A8, Partidos!$A:$C, 2, 0) - VLOOKUP(A8, Partidos!$A:$C, 3, 0)) = (B8 - C8), 3 + IF(AND(VLOOKUP(A8, Partidos!$A:$C, 2, 0) = B8, VLOOKUP(A8, Partidos!$A:$C, 3, 0) = C8), 2, 0), 0), 0)), 0) -> 0
A9: 8 | B9: 2 | C9: 2 | D9: =IFERROR(IF(OR(VLOOKUP(A9, Partidos!$A:$C, 2, 0)="", VLOOKUP(A9, Partidos!$A:$C, 3, 0)=""), 0, IF(SIGN(VLOOKUP(A9, Partidos!$A:$C, 2, 0) - VLOOKUP(A9, Partidos!$A:$C, 3, 0)) = SIGN(B9 - C9), 2 + IF((VLOOKUP(A9, Partidos!$A:$C, 2, 0) - VLOOKUP(A9, Partidos!$A:$C, 3, 0)) = (B9 - C9), 3 + IF(AND(VLOOKUP(A9, Partidos!$A:$C, 2, 0) = B9, VLOOKUP(A9, Partidos!$A:$C, 3, 0) = C9), 2, 0), 0), 0)), 0) -> 0
A10: 9 | B10: 2 | C10: 2 | D10: =IFERROR(IF(OR(VLOOKUP(A10, Partidos!$A:$C, 2, 0)="", VLOOKUP(A10, Partidos!$A:$C, 3, 0)=""), 0, IF(SIGN(VLOOKUP(A10, Partidos!$A:$C, 2, 0) - VLOOKUP(A10, Partidos!$A:$C, 3, 0)) = SIGN(B10 - C10), 2 + IF((VLOOKUP(A10, Partidos!$A:$C, 2, 0) - VLOOKUP(A10, Partidos!$A:$C, 3, 0)) = (B10 - C10), 3 + IF(AND(VLOOKUP(A10, Partidos!$A:$C, 2, 0) = B10, VLOOKUP(A10, Partidos!$A:$C, 3, 0) = C10), 2, 0), 0), 0)), 0) -> 0
A11: 10 | B11: 2 | C11: 2 | D11: =IFERROR(IF(OR(VLOOKUP(A11, Partidos!$A:$C, 2, 0)="", VLOOKUP(A11, Partidos!$A:$C, 3, 0)=""), 0, IF(SIGN(VLOOKUP(A11, Partidos!$A:$C, 2, 0) - VLOOKUP(A11, Partidos!$A:$C, 3, 0)) = SIGN(B11 - C11), 2 + IF((VLOOKUP(A11, Partidos!$A:$C, 2, 0) - VLOOKUP(A11, Partidos!$A:$C, 3, 0)) = (B11 - C11), 3 + IF(AND(VLOOKUP(A11, Partidos!$A:$C, 2, 0) = B11, VLOOKUP(A11, Partidos!$A:$C, 3, 0) = C11), 2, 0), 0), 0)), 0) -> 0
A12: 11 | B12: 2 | C12: 2 | D12: =IFERROR(IF(OR(VLOOKUP(A12, Partidos!$A:$C, 2, 0)="", VLOOKUP(A12, Partidos!$A:$C, 3, 0)=""), 0, IF(SIGN(VLOOKUP(A12, Partidos!$A:$C, 2, 0) - VLOOKUP(A12, Partidos!$A:$C, 3, 0)) = SIGN(B12 - C12), 2 + IF((VLOOKUP(A12, Partidos!$A:$C, 2, 0) - VLOOKUP(A12, Partidos!$A:$C, 3, 0)) = (B12 - C12), 3 + IF(AND(VLOOKUP(A12, Partidos!$A:$C, 2, 0) = B12, VLOOKUP(A12, Partidos!$A:$C, 3, 0) = C12), 2, 0), 0), 0)), 0) -> 0
A13: 12 | B13: 2 | C13: 2 | D13: =IFERROR(IF(OR(VLOOKUP(A13, Partidos!$A:$C, 2, 0)="", VLOOKUP(A13, Partidos!$A:$C, 3, 0)=""), 0, IF(SIGN(VLOOKUP(A13, Partidos!$A:$C, 2, 0) - VLOOKUP(A13, Partidos!$A:$C, 3, 0)) = SIGN(B13 - C13), 2 + IF((VLOOKUP(A13, Partidos!$A:$C, 2, 0) - VLOOKUP(A13, Partidos!$A:$C, 3, 0)) = (B13 - C13), 3 + IF(AND(VLOOKUP(A13, Partidos!$A:$C, 2, 0) = B13, VLOOKUP(A13, Partidos!$A:$C, 3, 0) = C13), 2, 0), 0), 0)), 0) -> 0
A14: 13 | B14: 2 | C14: 2 | D14: =IFERROR(IF(OR(VLOOKUP(A14, Partidos!$A:$C, 2, 0)="", VLOOKUP(A14, Partidos!$A:$C, 3, 0)=""), 0, IF(SIGN(VLOOKUP(A14, Partidos!$A:$C, 2, 0) - VLOOKUP(A14, Partidos!$A:$C, 3, 0)) = SIGN(B14 - C14), 2 + IF((VLOOKUP(A14, Partidos!$A:$C, 2, 0) - VLOOKUP(A14, Partidos!$A:$C, 3, 0)) = (B14 - C14), 3 + IF(AND(VLOOKUP(A14, Partidos!$A:$C, 2, 0) = B14, VLOOKUP(A14, Partidos!$A:$C, 3, 0) = C14), 2, 0), 0), 0)), 0) -> 0
... A26: 25 | B26: 2 | C26: 3 | D26: =IFERROR(IF(OR(VLOOKUP(A26, Partidos!$A:$C, 2, 0)="", VLOOKUP(A26, Partidos!$A:$C, 3, 0)=""), 0, IF(SIGN(VLOOKUP(A26, Partidos!$A:$C, 2, 0) - VLOOKUP(A26, Partidos!$A:$C, 3, 0)) = SIGN(B26 - C26), 2 + IF((VLOOKUP(A26, Partidos!$A:$C, 2, 0) - VLOOKUP(A26, Partidos!$A:$C, 3, 0)) = (B26 - C26), 3 + IF(AND(VLOOKUP(A26, Partidos!$A:$C, 2, 0) = B26, VLOOKUP(A26, Partidos!$A:$C, 3, 0) = C26), 2, 0), 0), 0)), 0) -> 0
D27: =IFERROR(IF(OR(VLOOKUP(A27, Partidos!$A:$C, 2, 0)="", VLOOKUP(A27, Partidos!$A:$C, 3, 0)=""), 0, IF(SIGN(VLOOKUP(A27, Partidos!$A:$C, 2, 0) - VLOOKUP(A27, Partidos!$A:$C, 3, 0)) = SIGN(B27 - C27), 2 + IF((VLOOKUP(A27, Partidos!$A:$C, 2, 0) - VLOOKUP(A27, Partidos!$A:$C, 3, 0)) = (B27 - C27), 3 + IF(AND(VLOOKUP(A27, Partidos!$A:$C, 2, 0) = B27, VLOOKUP(A27, Partidos!$A:$C, 3, 0) = C27), 2, 0), 0), 0)), 0) -> 0

Sheet Mariano
A1: ID Partido | B1: predict Eq1 | C1: PredictEq2 | D1: puntos | E1: Puntos totales
A2: 1 | B2: 1 | C2: 3 | D2: =IFERROR(IF(OR(VLOOKUP(A2, Partidos!$A:$C, 2, 0)="", VLOOKUP(A2, Partidos!$A:$C, 3, 0)=""), 0, IF(SIGN(VLOOKUP(A2, Partidos!$A:$C, 2, 0) - VLOOKUP(A2, Partidos!$A:$C, 3, 0)) = SIGN(B2 - C2), 2 + IF((VLOOKUP(A2, Partidos!$A:$C, 2, 0) - VLOOKUP(A2, Partidos!$A:$C, 3, 0)) = (B2 - C2), 3 + IF(AND(VLOOKUP(A2, Partidos!$A:$C, 2, 0) = B2, VLOOKUP(A2, Partidos!$A:$C, 3, 0) = C2), 2, 0), 0), 0)), 0) -> 7 | E2: =_xlfn.AGGREGATE(9, 6, D2:D100) -> 23
A3: 2 | B3: 3 | C3: 1 | D3: =IFERROR(IF(OR(VLOOKUP(A3, Partidos!$A:$C, 2, 0)="", VLOOKUP(A3, Partidos!$A:$C, 3, 0)=""), 0, IF(SIGN(VLOOKUP(A3, Partidos!$A:$C, 2, 0) - VLOOKUP(A3, Partidos!$A:$C, 3, 0)) = SIGN(B3 - C3), 2 + IF((VLOOKUP(A3, Partidos!$A:$C, 2, 0) - VLOOKUP(A3, Partidos!$A:$C, 3, 0)) = (B3 - C3), 3 + IF(AND(VLOOKUP(A3, Partidos!$A:$C, 2, 0) = B3, VLOOKUP(A3, Partidos!$A:$C, 3, 0) = C3), 2, 0), 0), 0)), 0) -> 0
A4: 3 | B4: 2 | C4: 2 | D4: =IFERROR(IF(OR(VLOOKUP(A4, Partidos!$A:$C, 2, 0)="", VLOOKUP(A4, Partidos!$A:$C, 3, 0)=""), 0, IF(SIGN(VLOOKUP(A4, Partidos!$A:$C, 2, 0) - VLOOKUP(A4, Partidos!$A:$C, 3, 0)) = SIGN(B4 - C4), 2 + IF((VLOOKUP(A4, Partidos!$A:$C, 2, 0) - VLOOKUP(A4, Partidos!$A:$C, 3, 0)) = (B4 - C4), 3 + IF(AND(VLOOKUP(A4, Partidos!$A:$C, 2, 0) = B4, VLOOKUP(A4, Partidos!$A:$C, 3, 0) = C4), 2, 0), 0), 0)), 0) -> 7
A5: 4 | B5: 2 | C5: 2 | D5: =IFERROR(IF(OR(VLOOKUP(A5, Partidos!$A:$C, 2, 0)="", VLOOKUP(A5, Partidos!$A:$C, 3, 0)=""), 0, IF(SIGN(VLOOKUP(A5, Partidos!$A:$C, 2, 0) - VLOOKUP(A5, Partidos!$A:$C, 3, 0)) = SIGN(B5 - C5), 2 + IF((VLOOKUP(A5, Partidos!$A:$C, 2, 0) - VLOOKUP(A5, Partidos!$A:$C, 3, 0)) = (B5 - C5), 3 + IF(AND(VLOOKUP(A5, Partidos!$A:$C, 2, 0) = B5, VLOOKUP(A5, Partidos!$A:$C, 3, 0) = C5), 2, 0), 0), 0)), 0) -> 0
A6: 5 | B6: 2 | C6: 2 | D6: =IFERROR(IF(OR(VLOOKUP(A6, Partidos!$A:$C, 2, 0)="", VLOOKUP(A6, Partidos!$A:$C, 3, 0)=""), 0, IF(SIGN(VLOOKUP(A6, Partidos!$A:$C, 2, 0) - VLOOKUP(A6, Partidos!$A:$C, 3, 0)) = SIGN(B6 - C6), 2 + IF((VLOOKUP(A6, Partidos!$A:$C, 2, 0) - VLOOKUP(A6, Partidos!$A:$C, 3, 0)) = (B6 - C6), 3 + IF(AND(VLOOKUP(A6, Partidos!$A:$C, 2, 0) = B6, VLOOKUP(A6, Partidos!$A:$C, 3, 0) = C6), 2, 0), 0), 0)), 0) -> 0
A7: 6 | B7: 2 | C7: 2 | D7: =IFERROR(IF(OR(VLOOKUP(A7, Partidos!$A:$C, 2, 0)="", VLOOKUP(A7, Partidos!$A:$C, 3, 0)=""), 0, IF(SIGN(VLOOKUP(A7, Partidos!$A:$C, 2, 0) - VLOOKUP(A7, Partidos!$A:$C, 3, 0)) = SIGN(B7 - C7), 2 + IF((VLOOKUP(A7, Partidos!$A:$C, 2, 0) - VLOOKUP(A7, Partidos!$A:$C, 3, 0)) = (B7 - C7), 3 + IF(AND(VLOOKUP(A7, Partidos!$A:$C, 2, 0) = B7, VLOOKUP(A7, Partidos!$A:$C, 3, 0) = C7), 2, 0), 0), 0)), 0) -> 0
A8: 7 | B8: 2 | C8: 2 | D8: =IFERROR(IF(OR(VLOOKUP(A8, Partidos!$A:$C, 2, 0)="", VLOOKUP(A8, Partidos!$A:$C, 3, 0)=""), 0, IF(SIGN(VLOOKUP(A8, Partidos!$A:$C, 2, 0) - VLOOKUP(A8, Partidos!$A:$C, 3, 0)) = SIGN(B8 - C8), 2 + IF((VLOOKUP(A8, Partidos!$A:$C, 2, 0) - VLOOKUP(A8, Partidos!$A:$C, 3, 0)) = (B8 - C8), 3 + IF(AND(VLOOKUP(A8, Partidos!$A:$C, 2, 0) = B8, VLOOKUP(A8, Partidos!$A:$C, 3, 0) = C8), 2, 0), 0), 0)), 0) -> 0
A9: 8 | B9: 2 | C9: 2 | D9: =IFERROR(IF(OR(VLOOKUP(A9, Partidos!$A:$C, 2, 0)="", VLOOKUP(A9, Partidos!$A:$C, 3, 0)=""), 0, IF(SIGN(VLOOKUP(A9, Partidos!$A:$C, 2, 0) - VLOOKUP(A9, Partidos!$A:$C, 3, 0)) = SIGN(B9 - C9), 2 + IF((VLOOKUP(A9, Partidos!$A:$C, 2, 0) - VLOOKUP(A9, Partidos!$A:$C, 3, 0)) = (B9 - C9), 3 + IF(AND(VLOOKUP(A9, Partidos!$A:$C, 2, 0) = B9, VLOOKUP(A9, Partidos!$A:$C, 3, 0) = C9), 2, 0), 0), 0)), 0) -> 0
A10: 9 | B10: 2 | C10: 2 | D10: =IFERROR(IF(OR(VLOOKUP(A10, Partidos!$A:$C, 2, 0)="", VLOOKUP(A10, Partidos!$A:$C, 3, 0)=""), 0, IF(SIGN(VLOOKUP(A10, Partidos!$A:$C, 2, 0) - VLOOKUP(A10, Partidos!$A:$C, 3, 0)) = SIGN(B10 - C10), 2 + IF((VLOOKUP(A10, Partidos!$A:$C, 2, 0) - VLOOKUP(A10, Partidos!$A:$C, 3, 0)) = (B10 - C10), 3 + IF(AND(VLOOKUP(A10, Partidos!$A:$C, 2, 0) = B10, VLOOKUP(A10, Partidos!$A:$C, 3, 0) = C10), 2, 0), 0), 0)), 0) -> 0
A11: 10 | B11: 2 | C11: 2 | D11: =IFERROR(IF(OR(VLOOKUP(A11, Partidos!$A:$C, 2, 0)="", VLOOKUP(A11, Partidos!$A:$C, 3, 0)=""), 0, IF(SIGN(VLOOKUP(A11, Partidos!$A:$C, 2, 0) - VLOOKUP(A11, Partidos!$A:$C, 3, 0)) = SIGN(B11 - C11), 2 + IF((VLOOKUP(A11, Partidos!$A:$C, 2, 0) - VLOOKUP(A11, Partidos!$A:$C, 3, 0)) = (B11 - C11), 3 + IF(AND(VLOOKUP(A11, Partidos!$A:$C, 2, 0) = B11, VLOOKUP(A11, Partidos!$A:$C, 3, 0) = C11), 2, 0), 0), 0)), 0) -> 0
A12: 11 | B12: 2 | C12: 2 | D12: =IFERROR(IF(OR(VLOOKUP(A12, Partidos!$A:$C, 2, 0)="", VLOOKUP(A12, Partidos!$A:$C, 3, 0)=""), 0, IF(SIGN(VLOOKUP(A12, Partidos!$A:$C, 2, 0) - VLOOKUP(A12, Partidos!$A:$C, 3, 0)) = SIGN(B12 - C12), 2 + IF((VLOOKUP(A12, Partidos!$A:$C, 2, 0) - VLOOKUP(A12, Partidos!$A:$C, 3, 0)) = (B12 - C12), 3 + IF(AND(VLOOKUP(A12, Partidos!$A:$C, 2, 0) = B12, VLOOKUP(A12, Partidos!$A:$C, 3, 0) = C12), 2, 0), 0), 0)), 0) -> 0
A13: 12 | B13: 2 | C13: 2 | D13: =IFERROR(IF(OR(VLOOKUP(A13, Partidos!$A:$C, 2, 0)="", VLOOKUP(A13, Partidos!$A:$C, 3, 0)=""), 0, IF(SIGN(VLOOKUP(A13, Partidos!$A:$C, 2, 0) - VLOOKUP(A13, Partidos!$A:$C, 3, 0)) = SIGN(B13 - C13), 2 + IF((VLOOKUP(A13, Partidos!$A:$C, 2, 0) - VLOOKUP(A13, Partidos!$A:$C, 3, 0)) = (B13 - C13), 3 + IF(AND(VLOOKUP(A13, Partidos!$A:$C, 2, 0) = B13, VLOOKUP(A13, Partidos!$A:$C, 3, 0) = C13), 2, 0), 0), 0)), 0) -> 0
A14: 13 | B14: 2 | C14: 2 | D14: =IFERROR(IF(OR(VLOOKUP(A14, Partidos!$A:$C, 2, 0)="", VLOOKUP(A14, Partidos!$A:$C, 3, 0)=""), 0, IF(SIGN(VLOOKUP(A14, Partidos!$A:$C, 2, 0) - VLOOKUP(A14, Partidos!$A:$C, 3, 0)) = SIGN(B14 - C14), 2 + IF((VLOOKUP(A14, Partidos!$A:$C, 2, 0) - VLOOKUP(A14, Partidos!$A:$C, 3, 0)) = (B14 - C14), 3 + IF(AND(VLOOKUP(A14, Partidos!$A:$C, 2, 0) = B14, VLOOKUP(A14, Partidos!$A:$C, 3, 0) = C14), 2, 0), 0), 0)), 0) -> 0
... A26: 25 | B26: 2 | C26: 3 | D26: =IFERROR(IF(OR(VLOOKUP(A26, Partidos!$A:$C, 2, 0)="", VLOOKUP(A26, Partidos!$A:$C, 3, 0)=""), 0, IF(SIGN(VLOOKUP(A26, Partidos!$A:$C, 2, 0) - VLOOKUP(A26, Partidos!$A:$C, 3, 0)) = SIGN(B26 - C26), 2 + IF((VLOOKUP(A26, Partidos!$A:$C, 2, 0) - VLOOKUP(A26, Partidos!$A:$C, 3, 0)) = (B26 - C26), 3 + IF(AND(VLOOKUP(A26, Partidos!$A:$C, 2, 0) = B26, VLOOKUP(A26, Partidos!$A:$C, 3, 0) = C26), 2, 0), 0), 0)), 0) -> 0
D27: =IFERROR(IF(OR(VLOOKUP(A27, Partidos!$A:$C, 2, 0)="", VLOOKUP(A27, Partidos!$A:$C, 3, 0)=""), 0, IF(SIGN(VLOOKUP(A27, Partidos!$A:$C, 2, 0) - VLOOKUP(A27, Partidos!$A:$C, 3, 0)) = SIGN(B27 - C27), 2 + IF((VLOOKUP(A27, Partidos!$A:$C, 2, 0) - VLOOKUP(A27, Partidos!$A:$C, 3, 0)) = (B27 - C27), 3 + IF(AND(VLOOKUP(A27, Partidos!$A:$C, 2, 0) = B27, VLOOKUP(A27, Partidos!$A:$C, 3, 0) = C27), 2, 0), 0), 0)), 0) -> 0

Sheet Jorge
A1: ID Partido | B1: predict Eq1 | C1: PredictEq2 | D1: puntos | E1: Puntos totales
A2: 1 | B2: 1 | C2: 3 | D2: =IFERROR(IF(OR(VLOOKUP(A2, Partidos!$A:$C, 2, 0)="", VLOOKUP(A2, Partidos!$A:$C, 3, 0)=""), 0, IF(SIGN(VLOOKUP(A2, Partidos!$A:$C, 2, 0) - VLOOKUP(A2, Partidos!$A:$C, 3, 0)) = SIGN(B2 - C2), 2 + IF((VLOOKUP(A2, Partidos!$A:$C, 2, 0) - VLOOKUP(A2, Partidos!$A:$C, 3, 0)) = (B2 - C2), 3 + IF(AND(VLOOKUP(A2, Partidos!$A:$C, 2, 0) = B2, VLOOKUP(A2, Partidos!$A:$C, 3, 0) = C2), 2, 0), 0), 0)), 0) -> 7 | E2: =_xlfn.AGGREGATE(9, 6, D2:D100) -> 23
A3: 2 | B3: 3 | C3: 1 | D3: =IFERROR(IF(OR(VLOOKUP(A3, Partidos!$A:$C, 2, 0)="", VLOOKUP(A3, Partidos!$A:$C, 3, 0)=""), 0, IF(SIGN(VLOOKUP(A3, Partidos!$A:$C, 2, 0) - VLOOKUP(A3, Partidos!$A:$C, 3, 0)) = SIGN(B3 - C3), 2 + IF((VLOOKUP(A3, Partidos!$A:$C, 2, 0) - VLOOKUP(A3, Partidos!$A:$C, 3, 0)) = (B3 - C3), 3 + IF(AND(VLOOKUP(A3, Partidos!$A:$C, 2, 0) = B3, VLOOKUP(A3, Partidos!$A:$C, 3, 0) = C3), 2, 0), 0), 0)), 0) -> 0
A4: 3 | B4: 2 | C4: 2 | D4: =IFERROR(IF(OR(VLOOKUP(A4, Partidos!$A:$C, 2, 0)="", VLOOKUP(A4, Partidos!$A:$C, 3, 0)=""), 0, IF(SIGN(VLOOKUP(A4, Partidos!$A:$C, 2, 0) - VLOOKUP(A4, Partidos!$A:$C, 3, 0)) = SIGN(B4 - C4), 2 + IF((VLOOKUP(A4, Partidos!$A:$C, 2, 0) - VLOOKUP(A4, Partidos!$A:$C, 3, 0)) = (B4 - C4), 3 + IF(AND(VLOOKUP(A4, Partidos!$A:$C, 2, 0) = B4, VLOOKUP(A4, Partidos!$A:$C, 3, 0) = C4), 2, 0), 0), 0)), 0) -> 7
A5: 4 | B5: 2 | C5: 2 | D5: =IFERROR(IF(OR(VLOOKUP(A5, Partidos!$A:$C, 2, 0)="", VLOOKUP(A5, Partidos!$A:$C, 3, 0)=""), 0, IF(SIGN(VLOOKUP(A5, Partidos!$A:$C, 2, 0) - VLOOKUP(A5, Partidos!$A:$C, 3, 0)) = SIGN(B5 - C5), 2 + IF((VLOOKUP(A5, Partidos!$A:$C, 2, 0) - VLOOKUP(A5, Partidos!$A:$C, 3, 0)) = (B5 - C5), 3 + IF(AND(VLOOKUP(A5, Partidos!$A:$C, 2, 0) = B5, VLOOKUP(A5, Partidos!$A:$C, 3, 0) = C5), 2, 0), 0), 0)), 0) -> 0
A6: 5 | B6: 2 | C6: 2 | D6: =IFERROR(IF(OR(VLOOKUP(A6, Partidos!$A:$C, 2, 0)="", VLOOKUP(A6, Partidos!$A:$C, 3, 0)=""), 0, IF(SIGN(VLOOKUP(A6, Partidos!$A:$C, 2, 0) - VLOOKUP(A6, Partidos!$A:$C, 3, 0)) = SIGN(B6 - C6), 2 + IF((VLOOKUP(A6, Partidos!$A:$C, 2, 0) - VLOOKUP(A6, Partidos!$A:$C, 3, 0)) = (B6 - C6), 3 + IF(AND(VLOOKUP(A6, Partidos!$A:$C, 2, 0) = B6, VLOOKUP(A6, Partidos!$A:$C, 3, 0) = C6), 2, 0), 0), 0)), 0) -> 0
A7: 6 | B7: 2 | C7: 2 | D7: =IFERROR(IF(OR(VLOOKUP(A7, Partidos!$A:$C, 2, 0)="", VLOOKUP(A7, Partidos!$A:$C, 3, 0)=""), 0, IF(SIGN(VLOOKUP(A7, Partidos!$A:$C, 2, 0) - VLOOKUP(A7, Partidos!$A:$C, 3, 0)) = SIGN(B7 - C7), 2 + IF((VLOOKUP(A7, Partidos!$A:$C, 2, 0) - VLOOKUP(A7, Partidos!$A:$C, 3, 0)) = (B7 - C7), 3 + IF(AND(VLOOKUP(A7, Partidos!$A:$C, 2, 0) = B7, VLOOKUP(A7, Partidos!$A:$C, 3, 0) = C7), 2, 0), 0), 0)), 0) -> 0
A8: 7 | B8: 2 | C8: 2 | D8: =IFERROR(IF(OR(VLOOKUP(A8, Partidos!$A:$C, 2, 0)="", VLOOKUP(A8, Partidos!$A:$C, 3, 0)=""), 0, IF(SIGN(VLOOKUP(A8, Partidos!$A:$C, 2, 0) - VLOOKUP(A8, Partidos!$A:$C, 3, 0)) = SIGN(B8 - C8), 2 + IF((VLOOKUP(A8, Partidos!$A:$C, 2, 0) - VLOOKUP(A8, Partidos!$A:$C, 3, 0)) = (B8 - C8), 3 + IF(AND(VLOOKUP(A8, Partidos!$A:$C, 2, 0) = B8, VLOOKUP(A8, Partidos!$A:$C, 3, 0) = C8), 2, 0), 0), 0)), 0) -> 0
A9: 8 | B9: 2 | C9: 2 | D9: =IFERROR(IF(OR(VLOOKUP(A9, Partidos!$A:$C, 2, 0)="", VLOOKUP(A9, Partidos!$A:$C, 3, 0)=""), 0, IF(SIGN(VLOOKUP(A9, Partidos!$A:$C, 2, 0) - VLOOKUP(A9, Partidos!$A:$C, 3, 0)) = SIGN(B9 - C9), 2 + IF((VLOOKUP(A9, Partidos!$A:$C, 2, 0) - VLOOKUP(A9, Partidos!$A:$C, 3, 0)) = (B9 - C9), 3 + IF(AND(VLOOKUP(A9, Partidos!$A:$C, 2, 0) = B9, VLOOKUP(A9, Partidos!$A:$C, 3, 0) = C9), 2, 0), 0), 0)), 0) -> 0
A10: 9 | B10: 2 | C10: 2 | D10: =IFERROR(IF(OR(VLOOKUP(A10, Partidos!$A:$C, 2, 0)="", VLOOKUP(A10, Partidos!$A:$C, 3, 0)=""), 0, IF(SIGN(VLOOKUP(A10, Partidos!$A:$C, 2, 0) - VLOOKUP(A10, Partidos!$A:$C, 3, 0)) = SIGN(B10 - C10), 2 + IF((VLOOKUP(A10, Partidos!$A:$C, 2, 0) - VLOOKUP(A10, Partidos!$A:$C, 3, 0)) = (B10 - C10), 3 + IF(AND(VLOOKUP(A10, Partidos!$A:$C, 2, 0) = B10, VLOOKUP(A10, Partidos!$A:$C, 3, 0) = C10), 2, 0), 0), 0)), 0) -> 0
A11: 10 | B11: 2 | C11: 2 | D11: =IFERROR(IF(OR(VLOOKUP(A11, Partidos!$A:$C, 2, 0)="", VLOOKUP(A11, Partidos!$A:$C, 3, 0)=""), 0, IF(SIGN(VLOOKUP(A11, Partidos!$A:$C, 2, 0) - VLOOKUP(A11, Partidos!$A:$C, 3, 0)) = SIGN(B11 - C11), 2 + IF((VLOOKUP(A11, Partidos!$A:$C, 2, 0) - VLOOKUP(A11, Partidos!$A:$C, 3, 0)) = (B11 - C11), 3 + IF(AND(VLOOKUP(A11, Partidos!$A:$C, 2, 0) = B11, VLOOKUP(A11, Partidos!$A:$C, 3, 0) = C11), 2, 0), 0), 0)), 0) -> 0
A12: 11 | B12: 2 | C12: 2 | D12: =IFERROR(IF(OR(VLOOKUP(A12, Partidos!$A:$C, 2, 0)="", VLOOKUP(A12, Partidos!$A:$C, 3, 0)=""), 0, IF(SIGN(VLOOKUP(A12, Partidos!$A:$C, 2, 0) - VLOOKUP(A12, Partidos!$A:$C, 3, 0)) = SIGN(B12 - C12), 2 + IF((VLOOKUP(A12, Partidos!$A:$C, 2, 0) - VLOOKUP(A12, Partidos!$A:$C, 3, 0)) = (B12 - C12), 3 + IF(AND(VLOOKUP(A12, Partidos!$A:$C, 2, 0) = B12, VLOOKUP(A12, Partidos!$A:$C, 3, 0) = C12), 2, 0), 0), 0)), 0) -> 0
A13: 12 | B13: 2 | C13: 2 | D13: =IFERROR(IF(OR(VLOOKUP(A13, Partidos!$A:$C, 2, 0)="", VLOOKUP(A13, Partidos!$A:$C, 3, 0)=""), 0, IF(SIGN(VLOOKUP(A13, Partidos!$A:$C, 2, 0) - VLOOKUP(A13, Partidos!$A:$C, 3, 0)) = SIGN(B13 - C13), 2 + IF((VLOOKUP(A13, Partidos!$A:$C, 2, 0) - VLOOKUP(A13, Partidos!$A:$C, 3, 0)) = (B13 - C13), 3 + IF(AND(VLOOKUP(A13, Partidos!$A:$C, 2, 0) = B13, VLOOKUP(A13, Partidos!$A:$C, 3, 0) = C13), 2, 0), 0), 0)), 0) -> 0
A14: 13 | B14: 2 | C14: 2 | D14: =IFERROR(IF(OR(VLOOKUP(A14, Partidos!$A:$C, 2, 0)="", VLOOKUP(A14, Partidos!$A:$C, 3, 0)=""), 0, IF(SIGN(VLOOKUP(A14, Partidos!$A:$C, 2, 0) - VLOOKUP(A14, Partidos!$A:$C, 3, 0)) = SIGN(B14 - C14), 2 + IF((VLOOKUP(A14, Partidos!$A:$C, 2, 0) - VLOOKUP(A14, Partidos!$A:$C, 3, 0)) = (B14 - C14), 3 + IF(AND(VLOOKUP(A14, Partidos!$A:$C, 2, 0) = B14, VLOOKUP(A14, Partidos!$A:$C, 3, 0) = C14), 2, 0), 0), 0)), 0) -> 0
... A26: 25 | B26: 2 | C26: 3 | D26: =IFERROR(IF(OR(VLOOKUP(A26, Partidos!$A:$C, 2, 0)="", VLOOKUP(A26, Partidos!$A:$C, 3, 0)=""), 0, IF(SIGN(VLOOKUP(A26, Partidos!$A:$C, 2, 0) - VLOOKUP(A26, Partidos!$A:$C, 3, 0)) = SIGN(B26 - C26), 2 + IF((VLOOKUP(A26, Partidos!$A:$C, 2, 0) - VLOOKUP(A26, Partidos!$A:$C, 3, 0)) = (B26 - C26), 3 + IF(AND(VLOOKUP(A26, Partidos!$A:$C, 2, 0) = B26, VLOOKUP(A26, Partidos!$A:$C, 3, 0) = C26), 2, 0), 0), 0)), 0) -> 0
D27: =IFERROR(IF(OR(VLOOKUP(A27, Partidos!$A:$C, 2, 0)="", VLOOKUP(A27, Partidos!$A:$C, 3, 0)=""), 0, IF(SIGN(VLOOKUP(A27, Partidos!$A:$C, 2, 0) - VLOOKUP(A27, Partidos!$A:$C, 3, 0)) = SIGN(B27 - C27), 2 + IF((VLOOKUP(A27, Partidos!$A:$C, 2, 0) - VLOOKUP(A27, Partidos!$A:$C, 3, 0)) = (B27 - C27), 3 + IF(AND(VLOOKUP(A27, Partidos!$A:$C, 2, 0) = B27, VLOOKUP(A27, Partidos!$A:$C, 3, 0) = C27), 2, 0), 0), 0)), 0) -> 0

Sheet Joaquin
A1: ID Partido | B1: predict Eq1 | C1: PredictEq2 | D1: puntos | E1: Puntos totales
A2: 1 | B2: 1 | C2: 3 | D2: =IFERROR(IF(OR(VLOOKUP(A2, Partidos!$A:$C, 2, 0)="", VLOOKUP(A2, Partidos!$A:$C, 3, 0)=""), 0, IF(SIGN(VLOOKUP(A2, Partidos!$A:$C, 2, 0) - VLOOKUP(A2, Partidos!$A:$C, 3, 0)) = SIGN(B2 - C2), 2 + IF((VLOOKUP(A2, Partidos!$A:$C, 2, 0) - VLOOKUP(A2, Partidos!$A:$C, 3, 0)) = (B2 - C2), 3 + IF(AND(VLOOKUP(A2, Partidos!$A:$C, 2, 0) = B2, VLOOKUP(A2, Partidos!$A:$C, 3, 0) = C2), 2, 0), 0), 0)), 0) -> 7 | E2: =_xlfn.AGGREGATE(9, 6, D2:D100) -> 23
A3: 2 | B3: 3 | C3: 1 | D3: =IFERROR(IF(OR(VLOOKUP(A3, Partidos!$A:$C, 2, 0)="", VLOOKUP(A3, Partidos!$A:$C, 3, 0)=""), 0, IF(SIGN(VLOOKUP(A3, Partidos!$A:$C, 2, 0) - VLOOKUP(A3, Partidos!$A:$C, 3, 0)) = SIGN(B3 - C3), 2 + IF((VLOOKUP(A3, Partidos!$A:$C, 2, 0) - VLOOKUP(A3, Partidos!$A:$C, 3, 0)) = (B3 - C3), 3 + IF(AND(VLOOKUP(A3, Partidos!$A:$C, 2, 0) = B3, VLOOKUP(A3, Partidos!$A:$C, 3, 0) = C3), 2, 0), 0), 0)), 0) -> 0
A4: 3 | B4: 2 | C4: 2 | D4: =IFERROR(IF(OR(VLOOKUP(A4, Partidos!$A:$C, 2, 0)="", VLOOKUP(A4, Partidos!$A:$C, 3, 0)=""), 0, IF(SIGN(VLOOKUP(A4, Partidos!$A:$C, 2, 0) - VLOOKUP(A4, Partidos!$A:$C, 3, 0)) = SIGN(B4 - C4), 2 + IF((VLOOKUP(A4, Partidos!$A:$C, 2, 0) - VLOOKUP(A4, Partidos!$A:$C, 3, 0)) = (B4 - C4), 3 + IF(AND(VLOOKUP(A4, Partidos!$A:$C, 2, 0) = B4, VLOOKUP(A4, Partidos!$A:$C, 3, 0) = C4), 2, 0), 0), 0)), 0) -> 7
A5: 4 | B5: 2 | C5: 2 | D5: =IFERROR(IF(OR(VLOOKUP(A5, Partidos!$A:$C, 2, 0)="", VLOOKUP(A5, Partidos!$A:$C, 3, 0)=""), 0, IF(SIGN(VLOOKUP(A5, Partidos!$A:$C, 2, 0) - VLOOKUP(A5, Partidos!$A:$C, 3, 0)) = SIGN(B5 - C5), 2 + IF((VLOOKUP(A5, Partidos!$A:$C, 2, 0) - VLOOKUP(A5, Partidos!$A:$C, 3, 0)) = (B5 - C5), 3 + IF(AND(VLOOKUP(A5, Partidos!$A:$C, 2, 0) = B5, VLOOKUP(A5, Partidos!$A:$C, 3, 0) = C5), 2, 0), 0), 0)), 0) -> 0
A6: 5 | B6: 2 | C6: 2 | D6: =IFERROR(IF(OR(VLOOKUP(A6, Partidos!$A:$C, 2, 0)="", VLOOKUP(A6, Partidos!$A:$C, 3, 0)=""), 0, IF(SIGN(VLOOKUP(A6, Partidos!$A:$C, 2, 0) - VLOOKUP(A6, Partidos!$A:$C, 3, 0)) = SIGN(B6 - C6), 2 + IF((VLOOKUP(A6, Partidos!$A:$C, 2, 0) - VLOOKUP(A6, Partidos!$A:$C, 3, 0)) = (B6 - C6), 3 + IF(AND(VLOOKUP(A6, Partidos!$A:$C, 2, 0) = B6, VLOOKUP(A6, Partidos!$A:$C, 3, 0) = C6), 2, 0), 0), 0)), 0) -> 0
A7: 6 | B7: 2 | C7: 2 | D7: =IFERROR(IF(OR(VLOOKUP(A7, Partidos!$A:$C, 2, 0)="", VLOOKUP(A7, Partidos!$A:$C, 3, 0)=""), 0, IF(SIGN(VLOOKUP(A7, Partidos!$A:$C, 2, 0) - VLOOKUP(A7, Partidos!$A:$C, 3, 0)) = SIGN(B7 - C7), 2 + IF((VLOOKUP(A7, Partidos!$A:$C, 2, 0) - VLOOKUP(A7, Partidos!$A:$C, 3, 0)) = (B7 - C7), 3 + IF(AND(VLOOKUP(A7, Partidos!$A:$C, 2, 0) = B7, VLOOKUP(A7, Partidos!$A:$C, 3, 0) = C7), 2, 0), 0), 0)), 0) -> 0
A8: 7 | B8: 2 | C8: 2 | D8: =IFERROR(IF(OR(VLOOKUP(A8, Partidos!$A:$C, 2, 0)="", VLOOKUP(A8, Partidos!$A:$C, 3, 0)=""), 0, IF(SIGN(VLOOKUP(A8, Partidos!$A:$C, 2, 0) - VLOOKUP(A8, Partidos!$A:$C, 3, 0)) = SIGN(B8 - C8), 2 + IF((VLOOKUP(A8, Partidos!$A:$C, 2, 0) - VLOOKUP(A8, Partidos!$A:$C, 3, 0)) = (B8 - C8), 3 + IF(AND(VLOOKUP(A8, Partidos!$A:$C, 2, 0) = B8, VLOOKUP(A8, Partidos!$A:$C, 3, 0) = C8), 2, 0), 0), 0)), 0) -> 0
A9: 8 | B9: 2 | C9: 2 | D9: =IFERROR(IF(OR(VLOOKUP(A9, Partidos!$A:$C, 2, 0)="", VLOOKUP(A9, Partidos!$A:$C, 3, 0)=""), 0, IF(SIGN(VLOOKUP(A9, Partidos!$A:$C, 2, 0) - VLOOKUP(A9, Partidos!$A:$C, 3, 0)) = SIGN(B9 - C9), 2 + IF((VLOOKUP(A9, Partidos!$A:$C, 2, 0) - VLOOKUP(A9, Partidos!$A:$C, 3, 0)) = (B9 - C9), 3 + IF(AND(VLOOKUP(A9, Partidos!$A:$C, 2, 0) = B9, VLOOKUP(A9, Partidos!$A:$C, 3, 0) = C9), 2, 0), 0), 0)), 0) -> 0
A10: 9 | B10: 2 | C10: 2 | D10: =IFERROR(IF(OR(VLOOKUP(A10, Partidos!$A:$C, 2, 0)="", VLOOKUP(A10, Partidos!$A:$C, 3, 0)=""), 0, IF(SIGN(VLOOKUP(A10, Partidos!$A:$C, 2, 0) - VLOOKUP(A10, Partidos!$A:$C, 3, 0)) = SIGN(B10 - C10), 2 + IF((VLOOKUP(A10, Partidos!$A:$C, 2, 0) - VLOOKUP(A10, Partidos!$A:$C, 3, 0)) = (B10 - C10), 3 + IF(AND(VLOOKUP(A10, Partidos!$A:$C, 2, 0) = B10, VLOOKUP(A10, Partidos!$A:$C, 3, 0) = C10), 2, 0), 0), 0)), 0) -> 0
A11: 10 | B11: 2 | C11: 2 | D11: =IFERROR(IF(OR(VLOOKUP(A11, Partidos!$A:$C, 2, 0)="", VLOOKUP(A11, Partidos!$A:$C, 3, 0)=""), 0, IF(SIGN(VLOOKUP(A11, Partidos!$A:$C, 2, 0) - VLOOKUP(A11, Partidos!$A:$C, 3, 0)) = SIGN(B11 - C11), 2 + IF((VLOOKUP(A11, Partidos!$A:$C, 2, 0) - VLOOKUP(A11, Partidos!$A:$C, 3, 0)) = (B11 - C11), 3 + IF(AND(VLOOKUP(A11, Partidos!$A:$C, 2, 0) = B11, VLOOKUP(A11, Partidos!$A:$C, 3, 0) = C11), 2, 0), 0), 0)), 0) -> 0
A12: 11 | B12: 2 | C12: 2 | D12: =IFERROR(IF(OR(VLOOKUP(A12, Partidos!$A:$C, 2, 0)="", VLOOKUP(A12, Partidos!$A:$C, 3, 0)=""), 0, IF(SIGN(VLOOKUP(A12, Partidos!$A:$C, 2, 0) - VLOOKUP(A12, Partidos!$A:$C, 3, 0)) = SIGN(B12 - C12), 2 + IF((VLOOKUP(A12, Partidos!$A:$C, 2, 0) - VLOOKUP(A12, Partidos!$A:$C, 3, 0)) = (B12 - C12), 3 + IF(AND(VLOOKUP(A12, Partidos!$A:$C, 2, 0) = B12, VLOOKUP(A12, Partidos!$A:$C, 3, 0) = C12), 2, 0), 0), 0)), 0) -> 0
A13: 12 | B13: 2 | C13: 2 | D13: =IFERROR(IF(OR(VLOOKUP(A13, Partidos!$A:$C, 2, 0)="", VLOOKUP(A13, Partidos!$A:$C, 3, 0)=""), 0, IF(SIGN(VLOOKUP(A13, Partidos!$A:$C, 2, 0) - VLOOKUP(A13, Partidos!$A:$C, 3, 0)) = SIGN(B13 - C13), 2 + IF((VLOOKUP(A13, Partidos!$A:$C, 2, 0) - VLOOKUP(A13, Partidos!$A:$C, 3, 0)) = (B13 - C13), 3 + IF(AND(VLOOKUP(A13, Partidos!$A:$C, 2, 0) = B13, VLOOKUP(A13, Partidos!$A:$C, 3, 0) = C13), 2, 0), 0), 0)), 0) -> 0
A14: 13 | B14: 2 | C14: 2 | D14: =IFERROR(IF(OR(VLOOKUP(A14, Partidos!$A:$C, 2, 0)="", VLOOKUP(A14, Partidos!$A:$C, 3, 0)=""), 0, IF(SIGN(VLOOKUP(A14, Partidos!$A:$C, 2, 0) - VLOOKUP(A14, Partidos!$A:$C, 3, 0)) = SIGN(B14 - C14), 2 + IF((VLOOKUP(A14, Partidos!$A:$C, 2, 0) - VLOOKUP(A14, Partidos!$A:$C, 3, 0)) = (B14 - C14), 3 + IF(AND(VLOOKUP(A14, Partidos!$A:$C, 2, 0) = B14, VLOOKUP(A14, Partidos!$A:$C, 3, 0) = C14), 2, 0), 0), 0)), 0) -> 0
... A26: 25 | B26: 2 | C26: 3 | D26: =IFERROR(IF(OR(VLOOKUP(A26, Partidos!$A:$C, 2, 0)="", VLOOKUP(A26, Partidos!$A:$C, 3, 0)=""), 0, IF(SIGN(VLOOKUP(A26, Partidos!$A:$C, 2, 0) - VLOOKUP(A26, Partidos!$A:$C, 3, 0)) = SIGN(B26 - C26), 2 + IF((VLOOKUP(A26, Partidos!$A:$C, 2, 0) - VLOOKUP(A26, Partidos!$A:$C, 3, 0)) = (B26 - C26), 3 + IF(AND(VLOOKUP(A26, Partidos!$A:$C, 2, 0) = B26, VLOOKUP(A26, Partidos!$A:$C, 3, 0) = C26), 2, 0), 0), 0)), 0) -> 0
D27: =IFERROR(IF(OR(VLOOKUP(A27, Partidos!$A:$C, 2, 0)="", VLOOKUP(A27, Partidos!$A:$C, 3, 0)=""), 0, IF(SIGN(VLOOKUP(A27, Partidos!$A:$C, 2, 0) - VLOOKUP(A27, Partidos!$A:$C, 3, 0)) = SIGN(B27 - C27), 2 + IF((VLOOKUP(A27, Partidos!$A:$C, 2, 0) - VLOOKUP(A27, Partidos!$A:$C, 3, 0)) = (B27 - C27), 3 + IF(AND(VLOOKUP(A27, Partidos!$A:$C, 2, 0) = B27, VLOOKUP(A27, Partidos!$A:$C, 3, 0) = C27), 2, 0), 0), 0)), 0) -> 0

Sheet Elizabeth
A1: ID Partido | B1: predict Eq1 | C1: PredictEq2 | D1: puntos | E1: Puntos totales
A2: 1 | B2: 1 | C2: 3 | D2: =IFERROR(IF(OR(VLOOKUP(A2, Partidos!$A:$C, 2, 0)="", VLOOKUP(A2, Partidos!$A:$C, 3, 0)=""), 0, IF(SIGN(VLOOKUP(A2, Partidos!$A:$C, 2, 0) - VLOOKUP(A2, Partidos!$A:$C, 3, 0)) = SIGN(B2 - C2), 2 + IF((VLOOKUP(A2, Partidos!$A:$C, 2, 0) - VLOOKUP(A2, Partidos!$A:$C, 3, 0)) = (B2 - C2), 3 + IF(AND(VLOOKUP(A2, Partidos!$A:$C, 2, 0) = B2, VLOOKUP(A2, Partidos!$A:$C, 3, 0) = C2), 2, 0), 0), 0)), 0) -> 7 | E2: =_xlfn.AGGREGATE(9, 6, D2:D100) -> 23
A3: 2 | B3: 3 | C3: 1 | D3: =IFERROR(IF(OR(VLOOKUP(A3, Partidos!$A:$C, 2, 0)="", VLOOKUP(A3, Partidos!$A:$C, 3, 0)=""), 0, IF(SIGN(VLOOKUP(A3, Partidos!$A:$C, 2, 0) - VLOOKUP(A3, Partidos!$A:$C, 3, 0)) = SIGN(B3 - C3), 2 + IF((VLOOKUP(A3, Partidos!$A:$C, 2, 0) - VLOOKUP(A3, Partidos!$A:$C, 3, 0)) = (B3 - C3), 3 + IF(AND(VLOOKUP(A3, Partidos!$A:$C, 2, 0) = B3, VLOOKUP(A3, Partidos!$A:$C, 3, 0) = C3), 2, 0), 0), 0)), 0) -> 0
A4: 3 | B4: 2 | C4: 2 | D4: =IFERROR(IF(OR(VLOOKUP(A4, Partidos!$A:$C, 2, 0)="", VLOOKUP(A4, Partidos!$A:$C, 3, 0)=""), 0, IF(SIGN(VLOOKUP(A4, Partidos!$A:$C, 2, 0) - VLOOKUP(A4, Partidos!$A:$C, 3, 0)) = SIGN(B4 - C4), 2 + IF((VLOOKUP(A4, Partidos!$A:$C, 2, 0) - VLOOKUP(A4, Partidos!$A:$C, 3, 0)) = (B4 - C4), 3 + IF(AND(VLOOKUP(A4, Partidos!$A:$C, 2, 0) = B4, VLOOKUP(A4, Partidos!$A:$C, 3, 0) = C4), 2, 0), 0), 0)), 0) -> 7
A5: 4 | B5: 2 | C5: 2 | D5: =IFERROR(IF(OR(VLOOKUP(A5, Partidos!$A:$C, 2, 0)="", VLOOKUP(A5, Partidos!$A:$C, 3, 0)=""), 0, IF(SIGN(VLOOKUP(A5, Partidos!$A:$C, 2, 0) - VLOOKUP(A5, Partidos!$A:$C, 3, 0)) = SIGN(B5 - C5), 2 + IF((VLOOKUP(A5, Partidos!$A:$C, 2, 0) - VLOOKUP(A5, Partidos!$A:$C, 3, 0)) = (B5 - C5), 3 + IF(AND(VLOOKUP(A5, Partidos!$A:$C, 2, 0) = B5, VLOOKUP(A5, Partidos!$A:$C, 3, 0) = C5), 2, 0), 0), 0)), 0) -> 0
A6: 5 | B6: 2 | C6: 2 | D6: =IFERROR(IF(OR(VLOOKUP(A6, Partidos!$A:$C, 2, 0)="", VLOOKUP(A6, Partidos!$A:$C, 3, 0)=""), 0, IF(SIGN(VLOOKUP(A6, Partidos!$A:$C, 2, 0) - VLOOKUP(A6, Partidos!$A:$C, 3, 0)) = SIGN(B6 - C6), 2 + IF((VLOOKUP(A6, Partidos!$A:$C, 2, 0) - VLOOKUP(A6, Partidos!$A:$C, 3, 0)) = (B6 - C6), 3 + IF(AND(VLOOKUP(A6, Partidos!$A:$C, 2, 0) = B6, VLOOKUP(A6, Partidos!$A:$C, 3, 0) = C6), 2, 0), 0), 0)), 0) -> 0
A7: 6 | B7: 2 | C7: 2 | D7: =IFERROR(IF(OR(VLOOKUP(A7, Partidos!$A:$C, 2, 0)="", VLOOKUP(A7, Partidos!$A:$C, 3, 0)=""), 0, IF(SIGN(VLOOKUP(A7, Partidos!$A:$C, 2, 0) - VLOOKUP(A7, Partidos!$A:$C, 3, 0)) = SIGN(B7 - C7), 2 + IF((VLOOKUP(A7, Partidos!$A:$C, 2, 0) - VLOOKUP(A7, Partidos!$A:$C, 3, 0)) = (B7 - C7), 3 + IF(AND(VLOOKUP(A7, Partidos!$A:$C, 2, 0) = B7, VLOOKUP(A7, Partidos!$A:$C, 3, 0) = C7), 2, 0), 0), 0)), 0) -> 0
A8: 7 | B8: 2 | C8: 2 | D8: =IFERROR(IF(OR(VLOOKUP(A8, Partidos!$A:$C, 2, 0)="", VLOOKUP(A8, Partidos!$A:$C, 3, 0)=""), 0, IF(SIGN(VLOOKUP(A8, Partidos!$A:$C, 2, 0) - VLOOKUP(A8, Partidos!$A:$C, 3, 0)) = SIGN(B8 - C8), 2 + IF((VLOOKUP(A8, Partidos!$A:$C, 2, 0) - VLOOKUP(A8, Partidos!$A:$C, 3, 0)) = (B8 - C8), 3 + IF(AND(VLOOKUP(A8, Partidos!$A:$C, 2, 0) = B8, VLOOKUP(A8, Partidos!$A:$C, 3, 0) = C8), 2, 0), 0), 0)), 0) -> 0
A9: 8 | B9: 2 | C9: 2 | D9: =IFERROR(IF(OR(VLOOKUP(A9, Partidos!$A:$C, 2, 0)="", VLOOKUP(A9, Partidos!$A:$C, 3, 0)=""), 0, IF(SIGN(VLOOKUP(A9, Partidos!$A:$C, 2, 0) - VLOOKUP(A9, Partidos!$A:$C, 3, 0)) = SIGN(B9 - C9), 2 + IF((VLOOKUP(A9, Partidos!$A:$C, 2, 0) - VLOOKUP(A9, Partidos!$A:$C, 3, 0)) = (B9 - C9), 3 + IF(AND(VLOOKUP(A9, Partidos!$A:$C, 2, 0) = B9, VLOOKUP(A9, Partidos!$A:$C, 3, 0) = C9), 2, 0), 0), 0)), 0) -> 0
A10: 9 | B10: 2 | C10: 2 | D10: =IFERROR(IF(OR(VLOOKUP(A10, Partidos!$A:$C, 2, 0)="", VLOOKUP(A10, Partidos!$A:$C, 3, 0)=""), 0, IF(SIGN(VLOOKUP(A10, Partidos!$A:$C, 2, 0) - VLOOKUP(A10, Partidos!$A:$C, 3, 0)) = SIGN(B10 - C10), 2 + IF((VLOOKUP(A10, Partidos!$A:$C, 2, 0) - VLOOKUP(A10, Partidos!$A:$C, 3, 0)) = (B10 - C10), 3 + IF(AND(VLOOKUP(A10, Partidos!$A:$C, 2, 0) = B10, VLOOKUP(A10, Partidos!$A:$C, 3, 0) = C10), 2, 0), 0), 0)), 0) -> 0
A11: 10 | B11: 2 | C11: 2 | D11: =IFERROR(IF(OR(VLOOKUP(A11, Partidos!$A:$C, 2, 0)="", VLOOKUP(A11, Partidos!$A:$C, 3, 0)=""), 0, IF(SIGN(VLOOKUP(A11, Partidos!$A:$C, 2, 0) - VLOOKUP(A11, Partidos!$A:$C, 3, 0)) = SIGN(B11 - C11), 2 + IF((VLOOKUP(A11, Partidos!$A:$C, 2, 0) - VLOOKUP(A11, Partidos!$A:$C, 3, 0)) = (B11 - C11), 3 + IF(AND(VLOOKUP(A11, Partidos!$A:$C, 2, 0) = B11, VLOOKUP(A11, Partidos!$A:$C, 3, 0) = C11), 2, 0), 0), 0)), 0) -> 0
A12: 11 | B12: 2 | C12: 2 | D12: =IFERROR(IF(OR(VLOOKUP(A12, Partidos!$A:$C, 2, 0)="", VLOOKUP(A12, Partidos!$A:$C, 3, 0)=""), 0, IF(SIGN(VLOOKUP(A12, Partidos!$A:$C, 2, 0) - VLOOKUP(A12, Partidos!$A:$C, 3, 0)) = SIGN(B12 - C12), 2 + IF((VLOOKUP(A12, Partidos!$A:$C, 2, 0) - VLOOKUP(A12, Partidos!$A:$C, 3, 0)) = (B12 - C12), 3 + IF(AND(VLOOKUP(A12, Partidos!$A:$C, 2, 0) = B12, VLOOKUP(A12, Partidos!$A:$C, 3, 0) = C12), 2, 0), 0), 0)), 0) -> 0
A13: 12 | B13: 2 | C13: 2 | D13: =IFERROR(IF(OR(VLOOKUP(A13, Partidos!$A:$C, 2, 0)="", VLOOKUP(A13, Partidos!$A:$C, 3, 0)=""), 0, IF(SIGN(VLOOKUP(A13, Partidos!$A:$C, 2, 0) - VLOOKUP(A13, Partidos!$A:$C, 3, 0)) = SIGN(B13 - C13), 2 + IF((VLOOKUP(A13, Partidos!$A:$C, 2, 0) - VLOOKUP(A13, Partidos!$A:$C, 3, 0)) = (B13 - C13), 3 + IF(AND(VLOOKUP(A13, Partidos!$A:$C, 2, 0) = B13, VLOOKUP(A13, Partidos!$A:$C, 3, 0) = C13), 2, 0), 0), 0)), 0) -> 0
A14: 13 | B14: 2 | C14: 2 | D14: =IFERROR(IF(OR(VLOOKUP(A14, Partidos!$A:$C, 2, 0)="", VLOOKUP(A14, Partidos!$A:$C, 3, 0)=""), 0, IF(SIGN(VLOOKUP(A14, Partidos!$A:$C, 2, 0) - VLOOKUP(A14, Partidos!$A:$C, 3, 0)) = SIGN(B14 - C14), 2 + IF((VLOOKUP(A14, Partidos!$A:$C, 2, 0) - VLOOKUP(A14, Partidos!$A:$C, 3, 0)) = (B14 - C14), 3 + IF(AND(VLOOKUP(A14, Partidos!$A:$C, 2, 0) = B14, VLOOKUP(A14, Partidos!$A:$C, 3, 0) = C14), 2, 0), 0), 0)), 0) -> 0
... A26: 25 | B26: 2 | C26: 3 | D26: =IFERROR(IF(OR(VLOOKUP(A26, Partidos!$A:$C, 2, 0)="", VLOOKUP(A26, Partidos!$A:$C, 3, 0)=""), 0, IF(SIGN(VLOOKUP(A26, Partidos!$A:$C, 2, 0) - VLOOKUP(A26, Partidos!$A:$C, 3, 0)) = SIGN(B26 - C26), 2 + IF((VLOOKUP(A26, Partidos!$A:$C, 2, 0) - VLOOKUP(A26, Partidos!$A:$C, 3, 0)) = (B26 - C26), 3 + IF(AND(VLOOKUP(A26, Partidos!$A:$C, 2, 0) = B26, VLOOKUP(A26, Partidos!$A:$C, 3, 0) = C26), 2, 0), 0), 0)), 0) -> 0
D27: =IFERROR(IF(OR(VLOOKUP(A27, Partidos!$A:$C, 2, 0)="", VLOOKUP(A27, Partidos!$A:$C, 3, 0)=""), 0, IF(SIGN(VLOOKUP(A27, Partidos!$A:$C, 2, 0) - VLOOKUP(A27, Partidos!$A:$C, 3, 0)) = SIGN(B27 - C27), 2 + IF((VLOOKUP(A27, Partidos!$A:$C, 2, 0) - VLOOKUP(A27, Partidos!$A:$C, 3, 0)) = (B27 - C27), 3 + IF(AND(VLOOKUP(A27, Partidos!$A:$C, 2, 0) = B27, VLOOKUP(A27, Partidos!$A:$C, 3, 0) = C27), 2, 0), 0), 0)), 0) -> 0

Sheet Pablo
A1: ID Partido | B1: predict Eq1 | C1: PredictEq2 | D1: puntos | E1: Puntos totales
A2: 1 | B2: 1 | C2: 3 | D2: =IFERROR(IF(OR(VLOOKUP(A2, Partidos!$A:$C, 2, 0)="", VLOOKUP(A2, Partidos!$A:$C, 3, 0)=""), 0, IF(SIGN(VLOOKUP(A2, Partidos!$A:$C, 2, 0) - VLOOKUP(A2, Partidos!$A:$C, 3, 0)) = SIGN(B2 - C2), 2 + IF((VLOOKUP(A2, Partidos!$A:$C, 2, 0) - VLOOKUP(A2, Partidos!$A:$C, 3, 0)) = (B2 - C2), 3 + IF(AND(VLOOKUP(A2, Partidos!$A:$C, 2, 0) = B2, VLOOKUP(A2, Partidos!$A:$C, 3, 0) = C2), 2, 0), 0), 0)), 0) -> 7 | E2: =_xlfn.AGGREGATE(9, 6, D2:D100) -> 23
A3: 2 | B3: 3 | C3: 1 | D3: =IFERROR(IF(OR(VLOOKUP(A3, Partidos!$A:$C, 2, 0)="", VLOOKUP(A3, Partidos!$A:$C, 3, 0)=""), 0, IF(SIGN(VLOOKUP(A3, Partidos!$A:$C, 2, 0) - VLOOKUP(A3, Partidos!$A:$C, 3, 0)) = SIGN(B3 - C3), 2 + IF((VLOOKUP(A3, Partidos!$A:$C, 2, 0) - VLOOKUP(A3, Partidos!$A:$C, 3, 0)) = (B3 - C3), 3 + IF(AND(VLOOKUP(A3, Partidos!$A:$C, 2, 0) = B3, VLOOKUP(A3, Partidos!$A:$C, 3, 0) = C3), 2, 0), 0), 0)), 0) -> 0
A4: 3 | B4: 2 | C4: 2 | D4: =IFERROR(IF(OR(VLOOKUP(A4, Partidos!$A:$C, 2, 0)="", VLOOKUP(A4, Partidos!$A:$C, 3, 0)=""), 0, IF(SIGN(VLOOKUP(A4, Partidos!$A:$C, 2, 0) - VLOOKUP(A4, Partidos!$A:$C, 3, 0)) = SIGN(B4 - C4), 2 + IF((VLOOKUP(A4, Partidos!$A:$C, 2, 0) - VLOOKUP(A4, Partidos!$A:$C, 3, 0)) = (B4 - C4), 3 + IF(AND(VLOOKUP(A4, Partidos!$A:$C, 2, 0) = B4, VLOOKUP(A4, Partidos!$A:$C, 3, 0) = C4), 2, 0), 0), 0)), 0) -> 7
A5: 4 | B5: 2 | C5: 2 | D5: =IFERROR(IF(OR(VLOOKUP(A5, Partidos!$A:$C, 2, 0)="", VLOOKUP(A5, Partidos!$A:$C, 3, 0)=""), 0, IF(SIGN(VLOOKUP(A5, Partidos!$A:$C, 2, 0) - VLOOKUP(A5, Partidos!$A:$C, 3, 0)) = SIGN(B5 - C5), 2 + IF((VLOOKUP(A5, Partidos!$A:$C, 2, 0) - VLOOKUP(A5, Partidos!$A:$C, 3, 0)) = (B5 - C5), 3 + IF(AND(VLOOKUP(A5, Partidos!$A:$C, 2, 0) = B5, VLOOKUP(A5, Partidos!$A:$C, 3, 0) = C5), 2, 0), 0), 0)), 0) -> 0
A6: 5 | B6: 2 | C6: 2 | D6: =IFERROR(IF(OR(VLOOKUP(A6, Partidos!$A:$C, 2, 0)="", VLOOKUP(A6, Partidos!$A:$C, 3, 0)=""), 0, IF(SIGN(VLOOKUP(A6, Partidos!$A:$C, 2, 0) - VLOOKUP(A6, Partidos!$A:$C, 3, 0)) = SIGN(B6 - C6), 2 + IF((VLOOKUP(A6, Partidos!$A:$C, 2, 0) - VLOOKUP(A6, Partidos!$A:$C, 3, 0)) = (B6 - C6), 3 + IF(AND(VLOOKUP(A6, Partidos!$A:$C, 2, 0) = B6, VLOOKUP(A6, Partidos!$A:$C, 3, 0) = C6), 2, 0), 0), 0)), 0) -> 0
A7: 6 | B7: 2 | C7: 2 | D7: =IFERROR(IF(OR(VLOOKUP(A7, Partidos!$A:$C, 2, 0)="", VLOOKUP(A7, Partidos!$A:$C, 3, 0)=""), 0, IF(SIGN(VLOOKUP(A7, Partidos!$A:$C, 2, 0) - VLOOKUP(A7, Partidos!$A:$C, 3, 0)) = SIGN(B7 - C7), 2 + IF((VLOOKUP(A7, Partidos!$A:$C, 2, 0) - VLOOKUP(A7, Partidos!$A:$C, 3, 0)) = (B7 - C7), 3 + IF(AND(VLOOKUP(A7, Partidos!$A:$C, 2, 0) = B7, VLOOKUP(A7, Partidos!$A:$C, 3, 0) = C7), 2, 0), 0), 0)), 0) -> 0
A8: 7 | B8: 2 | C8: 2 | D8: =IFERROR(IF(OR(VLOOKUP(A8, Partidos!$A:$C, 2, 0)="", VLOOKUP(A8, Partidos!$A:$C, 3, 0)=""), 0, IF(SIGN(VLOOKUP(A8, Partidos!$A:$C, 2, 0) - VLOOKUP(A8, Partidos!$A:$C, 3, 0)) = SIGN(B8 - C8), 2 + IF((VLOOKUP(A8, Partidos!$A:$C, 2, 0) - VLOOKUP(A8, Partidos!$A:$C, 3, 0)) = (B8 - C8), 3 + IF(AND(VLOOKUP(A8, Partidos!$A:$C, 2, 0) = B8, VLOOKUP(A8, Partidos!$A:$C, 3, 0) = C8), 2, 0), 0), 0)), 0) -> 0
A9: 8 | B9: 2 | C9: 2 | D9: =IFERROR(IF(OR(VLOOKUP(A9, Partidos!$A:$C, 2, 0)="", VLOOKUP(A9, Partidos!$A:$C, 3, 0)=""), 0, IF(SIGN(VLOOKUP(A9, Partidos!$A:$C, 2, 0) - VLOOKUP(A9, Partidos!$A:$C, 3, 0)) = SIGN(B9 - C9), 2 + IF((VLOOKUP(A9, Partidos!$A:$C, 2, 0) - VLOOKUP(A9, Partidos!$A:$C, 3, 0)) = (B9 - C9), 3 + IF(AND(VLOOKUP(A9, Partidos!$A:$C, 2, 0) = B9, VLOOKUP(A9, Partidos!$A:$C, 3, 0) = C9), 2, 0), 0), 0)), 0) -> 0
A10: 9 | B10: 2 | C10: 2 | D10: =IFERROR(IF(OR(VLOOKUP(A10, Partidos!$A:$C, 2, 0)="", VLOOKUP(A10, Partidos!$A:$C, 3, 0)=""), 0, IF(SIGN(VLOOKUP(A10, Partidos!$A:$C, 2, 0) - VLOOKUP(A10, Partidos!$A:$C, 3, 0)) = SIGN(B10 - C10), 2 + IF((VLOOKUP(A10, Partidos!$A:$C, 2, 0) - VLOOKUP(A10, Partidos!$A:$C, 3, 0)) = (B10 - C10), 3 + IF(AND(VLOOKUP(A10, Partidos!$A:$C, 2, 0) = B10, VLOOKUP(A10, Partidos!$A:$C, 3, 0) = C10), 2, 0), 0), 0)), 0) -> 0
A11: 10 | B11: 2 | C11: 2 | D11: =IFERROR(IF(OR(VLOOKUP(A11, Partidos!$A:$C, 2, 0)="", VLOOKUP(A11, Partidos!$A:$C, 3, 0)=""), 0, IF(SIGN(VLOOKUP(A11, Partidos!$A:$C, 2, 0) - VLOOKUP(A11, Partidos!$A:$C, 3, 0)) = SIGN(B11 - C11), 2 + IF((VLOOKUP(A11, Partidos!$A:$C, 2, 0) - VLOOKUP(A11, Partidos!$A:$C, 3, 0)) = (B11 - C11), 3 + IF(AND(VLOOKUP(A11, Partidos!$A:$C, 2, 0) = B11, VLOOKUP(A11, Partidos!$A:$C, 3, 0) = C11), 2, 0), 0), 0)), 0) -> 0
A12: 11 | B12: 2 | C12: 2 | D12: =IFERROR(IF(OR(VLOOKUP(A12, Partidos!$A:$C, 2, 0)="", VLOOKUP(A12, Partidos!$A:$C, 3, 0)=""), 0, IF(SIGN(VLOOKUP(A12, Partidos!$A:$C, 2, 0) - VLOOKUP(A12, Partidos!$A:$C, 3, 0)) = SIGN(B12 - C12), 2 + IF((VLOOKUP(A12, Partidos!$A:$C, 2, 0) - VLOOKUP(A12, Partidos!$A:$C, 3, 0)) = (B12 - C12), 3 + IF(AND(VLOOKUP(A12, Partidos!$A:$C, 2, 0) = B12, VLOOKUP(A12, Partidos!$A:$C, 3, 0) = C12), 2, 0), 0), 0)), 0) -> 0
A13: 12 | B13: 2 | C13: 2 | D13: =IFERROR(IF(OR(VLOOKUP(A13, Partidos!$A:$C, 2, 0)="", VLOOKUP(A13, Partidos!$A:$C, 3, 0)=""), 0, IF(SIGN(VLOOKUP(A13, Partidos!$A:$C, 2, 0) - VLOOKUP(A13, Partidos!$A:$C, 3, 0)) = SIGN(B13 - C13), 2 + IF((VLOOKUP(A13, Partidos!$A:$C, 2, 0) - VLOOKUP(A13, Partidos!$A:$C, 3, 0)) = (B13 - C13), 3 + IF(AND(VLOOKUP(A13, Partidos!$A:$C, 2, 0) = B13, VLOOKUP(A13, Partidos!$A:$C, 3, 0) = C13), 2, 0), 0), 0)), 0) -> 0
A14: 13 | B14: 2 | C14: 2 | D14: =IFERROR(IF(OR(VLOOKUP(A14, Partidos!$A:$C, 2, 0)="", VLOOKUP(A14, Partidos!$A:$C, 3, 0)=""), 0, IF(SIGN(VLOOKUP(A14, Partidos!$A:$C, 2, 0) - VLOOKUP(A14, Partidos!$A:$C, 3, 0)) = SIGN(B14 - C14), 2 + IF((VLOOKUP(A14, Partidos!$A:$C, 2, 0) - VLOOKUP(A14, Partidos!$A:$C, 3, 0)) = (B14 - C14), 3 + IF(AND(VLOOKUP(A14, Partidos!$A:$C, 2, 0) = B14, VLOOKUP(A14, Partidos!$A:$C, 3, 0) = C14), 2, 0), 0), 0)), 0) -> 0
... A26: 25 | B26: 2 | C26: 3 | D26: =IFERROR(IF(OR(VLOOKUP(A26, Partidos!$A:$C, 2, 0)="", VLOOKUP(A26, Partidos!$A:$C, 3, 0)=""), 0, IF(SIGN(VLOOKUP(A26, Partidos!$A:$C, 2, 0) - VLOOKUP(A26, Partidos!$A:$C, 3, 0)) = SIGN(B26 - C26), 2 + IF((VLOOKUP(A26, Partidos!$A:$C, 2, 0) - VLOOKUP(A26, Partidos!$A:$C, 3, 0)) = (B26 - C26), 3 + IF(AND(VLOOKUP(A26, Partidos!$A:$C, 2, 0) = B26, VLOOKUP(A26, Partidos!$A:$C, 3, 0) = C26), 2, 0), 0), 0)), 0) -> 0
D27: =IFERROR(IF(OR(VLOOKUP(A27, Partidos!$A:$C, 2, 0)="", VLOOKUP(A27, Partidos!$A:$C, 3, 0)=""), 0, IF(SIGN(VLOOKUP(A27, Partidos!$A:$C, 2, 0) - VLOOKUP(A27, Partidos!$A:$C, 3, 0)) = SIGN(B27 - C27), 2 + IF((VLOOKUP(A27, Partidos!$A:$C, 2, 0) - VLOOKUP(A27, Partidos!$A:$C, 3, 0)) = (B27 - C27), 3 + IF(AND(VLOOKUP(A27, Partidos!$A:$C, 2, 0) = B27, VLOOKUP(A27, Partidos!$A:$C, 3, 0) = C27), 2, 0), 0), 0)), 0) -> 0

Sheet Juan
A1: ID Partido | B1: predict Eq1 | C1: PredictEq2 | D1: puntos | E1: Puntos totales
A2: 1 | B2: 1 | C2: 3 | D2: =IFERROR(IF(OR(VLOOKUP(A2, Partidos!$A:$C, 2, 0)="", VLOOKUP(A2, Partidos!$A:$C, 3, 0)=""), 0, IF(SIGN(VLOOKUP(A2, Partidos!$A:$C, 2, 0) - VLOOKUP(A2, Partidos!$A:$C, 3, 0)) = SIGN(B2 - C2), 2 + IF((VLOOKUP(A2, Partidos!$A:$C, 2, 0) - VLOOKUP(A2, Partidos!$A:$C, 3, 0)) = (B2 - C2), 3 + IF(AND(VLOOKUP(A2, Partidos!$A:$C, 2, 0) = B2, VLOOKUP(A2, Partidos!$A:$C, 3, 0) = C2), 2, 0), 0), 0)), 0) -> 7 | E2: =_xlfn.AGGREGATE(9, 6, D2:D100) -> 23
A3: 2 | B3: 3 | C3: 1 | D3: =IFERROR(IF(OR(VLOOKUP(A3, Partidos!$A:$C, 2, 0)="", VLOOKUP(A3, Partidos!$A:$C, 3, 0)=""), 0, IF(SIGN(VLOOKUP(A3, Partidos!$A:$C, 2, 0) - VLOOKUP(A3, Partidos!$A:$C, 3, 0)) = SIGN(B3 - C3), 2 + IF((VLOOKUP(A3, Partidos!$A:$C, 2, 0) - VLOOKUP(A3, Partidos!$A:$C, 3, 0)) = (B3 - C3), 3 + IF(AND(VLOOKUP(A3, Partidos!$A:$C, 2, 0) = B3, VLOOKUP(A3, Partidos!$A:$C, 3, 0) = C3), 2, 0), 0), 0)), 0) -> 0
A4: 3 | B4: 2 | C4: 2 | D4: =IFERROR(IF(OR(VLOOKUP(A4, Partidos!$A:$C, 2, 0)="", VLOOKUP(A4, Partidos!$A:$C, 3, 0)=""), 0, IF(SIGN(VLOOKUP(A4, Partidos!$A:$C, 2, 0) - VLOOKUP(A4, Partidos!$A:$C, 3, 0)) = SIGN(B4 - C4), 2 + IF((VLOOKUP(A4, Partidos!$A:$C, 2, 0) - VLOOKUP(A4, Partidos!$A:$C, 3, 0)) = (B4 - C4), 3 + IF(AND(VLOOKUP(A4, Partidos!$A:$C, 2, 0) = B4, VLOOKUP(A4, Partidos!$A:$C, 3, 0) = C4), 2, 0), 0), 0)), 0) -> 7
A5: 4 | B5: 2 | C5: 2 | D5: =IFERROR(IF(OR(VLOOKUP(A5, Partidos!$A:$C, 2, 0)="", VLOOKUP(A5, Partidos!$A:$C, 3, 0)=""), 0, IF(SIGN(VLOOKUP(A5, Partidos!$A:$C, 2, 0) - VLOOKUP(A5, Partidos!$A:$C, 3, 0)) = SIGN(B5 - C5), 2 + IF((VLOOKUP(A5, Partidos!$A:$C, 2, 0) - VLOOKUP(A5, Partidos!$A:$C, 3, 0)) = (B5 - C5), 3 + IF(AND(VLOOKUP(A5, Partidos!$A:$C, 2, 0) = B5, VLOOKUP(A5, Partidos!$A:$C, 3, 0) = C5), 2, 0), 0), 0)), 0) -> 0
A6: 5 | B6: 2 | C6: 2 | D6: =IFERROR(IF(OR(VLOOKUP(A6, Partidos!$A:$C, 2, 0)="", VLOOKUP(A6, Partidos!$A:$C, 3, 0)=""), 0, IF(SIGN(VLOOKUP(A6, Partidos!$A:$C, 2, 0) - VLOOKUP(A6, Partidos!$A:$C, 3, 0)) = SIGN(B6 - C6), 2 + IF((VLOOKUP(A6, Partidos!$A:$C, 2, 0) - VLOOKUP(A6, Partidos!$A:$C, 3, 0)) = (B6 - C6), 3 + IF(AND(VLOOKUP(A6, Partidos!$A:$C, 2, 0) = B6, VLOOKUP(A6, Partidos!$A:$C, 3, 0) = C6), 2, 0), 0), 0)), 0) -> 0
A7: 6 | B7: 2 | C7: 2 | D7: =IFERROR(IF(OR(VLOOKUP(A7, Partidos!$A:$C, 2, 0)="", VLOOKUP(A7, Partidos!$A:$C, 3, 0)=""), 0, IF(SIGN(VLOOKUP(A7, Partidos!$A:$C, 2, 0) - VLOOKUP(A7, Partidos!$A:$C, 3, 0)) = SIGN(B7 - C7), 2 + IF((VLOOKUP(A7, Partidos!$A:$C, 2, 0) - VLOOKUP(A7, Partidos!$A:$C, 3, 0)) = (B7 - C7), 3 + IF(AND(VLOOKUP(A7, Partidos!$A:$C, 2, 0) = B7, VLOOKUP(A7, Partidos!$A:$C, 3, 0) = C7), 2, 0), 0), 0)), 0) -> 0
A8: 7 | B8: 2 | C8: 2 | D8: =IFERROR(IF(OR(VLOOKUP(A8, Partidos!$A:$C, 2, 0)="", VLOOKUP(A8, Partidos!$A:$C, 3, 0)=""), 0, IF(SIGN(VLOOKUP(A8, Partidos!$A:$C, 2, 0) - VLOOKUP(A8, Partidos!$A:$C, 3, 0)) = SIGN(B8 - C8), 2 + IF((VLOOKUP(A8, Partidos!$A:$C, 2, 0) - VLOOKUP(A8, Partidos!$A:$C, 3, 0)) = (B8 - C8), 3 + IF(AND(VLOOKUP(A8, Partidos!$A:$C, 2, 0) = B8, VLOOKUP(A8, Partidos!$A:$C, 3, 0) = C8), 2, 0), 0), 0)), 0) -> 0
A9: 8 | B9: 2 | C9: 2 | D9: =IFERROR(IF(OR(VLOOKUP(A9, Partidos!$A:$C, 2, 0)="", VLOOKUP(A9, Partidos!$A:$C, 3, 0)=""), 0, IF(SIGN(VLOOKUP(A9, Partidos!$A:$C, 2, 0) - VLOOKUP(A9, Partidos!$A:$C, 3, 0)) = SIGN(B9 - C9), 2 + IF((VLOOKUP(A9, Partidos!$A:$C, 2, 0) - VLOOKUP(A9, Partidos!$A:$C, 3, 0)) = (B9 - C9), 3 + IF(AND(VLOOKUP(A9, Partidos!$A:$C, 2, 0) = B9, VLOOKUP(A9, Partidos!$A:$C, 3, 0) = C9), 2, 0), 0), 0)), 0) -> 0
A10: 9 | B10: 2 | C10: 2 | D10: =IFERROR(IF(OR(VLOOKUP(A10, Partidos!$A:$C, 2, 0)="", VLOOKUP(A10, Partidos!$A:$C, 3, 0)=""), 0, IF(SIGN(VLOOKUP(A10, Partidos!$A:$C, 2, 0) - VLOOKUP(A10, Partidos!$A:$C, 3, 0)) = SIGN(B10 - C10), 2 + IF((VLOOKUP(A10, Partidos!$A:$C, 2, 0) - VLOOKUP(A10, Partidos!$A:$C, 3, 0)) = (B10 - C10), 3 + IF(AND(VLOOKUP(A10, Partidos!$A:$C, 2, 0) = B10, VLOOKUP(A10, Partidos!$A:$C, 3, 0) = C10), 2, 0), 0), 0)), 0) -> 0
A11: 10 | B11: 2 | C11: 2 | D11: =IFERROR(IF(OR(VLOOKUP(A11, Partidos!$A:$C, 2, 0)="", VLOOKUP(A11, Partidos!$A:$C, 3, 0)=""), 0, IF(SIGN(VLOOKUP(A11, Partidos!$A:$C, 2, 0) - VLOOKUP(A11, Partidos!$A:$C, 3, 0)) = SIGN(B11 - C11), 2 + IF((VLOOKUP(A11, Partidos!$A:$C, 2, 0) - VLOOKUP(A11, Partidos!$A:$C, 3, 0)) = (B11 - C11), 3 + IF(AND(VLOOKUP(A11, Partidos!$A:$C, 2, 0) = B11, VLOOKUP(A11, Partidos!$A:$C, 3, 0) = C11), 2, 0), 0), 0)), 0) -> 0
A12: 11 | B12: 2 | C12: 2 | D12: =IFERROR(IF(OR(VLOOKUP(A12, Partidos!$A:$C, 2, 0)="", VLOOKUP(A12, Partidos!$A:$C, 3, 0)=""), 0, IF(SIGN(VLOOKUP(A12, Partidos!$A:$C, 2, 0) - VLOOKUP(A12, Partidos!$A:$C, 3, 0)) = SIGN(B12 - C12), 2 + IF((VLOOKUP(A12, Partidos!$A:$C, 2, 0) - VLOOKUP(A12, Partidos!$A:$C, 3, 0)) = (B12 - C12), 3 + IF(AND(VLOOKUP(A12, Partidos!$A:$C, 2, 0) = B12, VLOOKUP(A12, Partidos!$A:$C, 3, 0) = C12), 2, 0), 0), 0)), 0) -> 0
